<?xml version="1.0" ?>
<!-- =================================================================================== -->
<!-- |    This document was autogenerated by xacro from robot.xacro                    | -->
<!-- |    EDITING THIS FILE BY HAND IS NOT RECOMMENDED                                 | -->
<!-- =================================================================================== -->
<robot name="galbot_one_golf">
  <joint name="leg_joint" type="fixed">
    <parent link="omni_chassis_leg_mount_link"/>
    <child link="leg_base_link"/>
  </joint>
  <link name="leg_base_link">
    <inertial>
      <origin xyz="7e-05 -0.05414 0"/>
      <mass value="1.58"/>
      <inertia ixx="0.00797474" ixy="8.35e-06" ixz="2e-08" iyy="0.00248067" iyz="6.9e-07" izz="0.00797203"/>
    </inertial>
  </link>
  <link name="leg_link1">
    <inertial>
      <origin xyz="0.22308 0.00065 -0.03018"/>
      <mass value="17.206"/>
      <inertia ixx="0.07124549" ixy="0.00349977" ixz="0.12482873" iyy="1.69951784" iyz="0.00023749" izz="1.67846222"/>
    </inertial>
    <visual>
      <geometry>
        <mesh filename="package://galbot_one_golf_description/meshes/visual/leg/leg1.glb"/>
      </geometry>
    </visual>
    <collision>
      <geometry>
        <mesh filename="package://galbot_one_golf_description/meshes/collision/leg/link1.stl"/>
      </geometry>
    </collision>
  </link>
  <joint name="leg_joint1" type="revolute">
    <origin rpy="1.5707963267948966 -0.385 3.141592653589793"/>
    <parent link="leg_base_link"/>
    <child link="leg_link1"/>
    <axis xyz="0 0 1"/>
    <limit effort="169" lower="0.0" upper="0.9374" velocity="1"/>
  </joint>
  <link name="leg_link2">
    <inertial>
      <origin xyz="0.1798 0.00017 0.04174"/>
      <mass value="7.611"/>
      <inertia ixx="0.08014216" ixy="0.00014962" ixz="0.05492423" iyy="0.49511503" iyz="0.00010258" izz="0.43725146"/>
    </inertial>
    <visual>
      <geometry>
        <mesh filename="package://galbot_one_golf_description/meshes/visual/leg/leg2.glb"/>
      </geometry>
    </visual>
    <collision>
      <geometry>
        <mesh filename="package://galbot_one_golf_description/meshes/collision/leg/link2.stl"/>
      </geometry>
    </collision>
  </link>
  <joint name="leg_joint2" type="revolute">
    <origin rpy="3.141592653589793 0 2.7566" xyz="0.45 0 0"/>
    <parent link="leg_link1"/>
    <child link="leg_link2"/>
    <axis xyz="0 0 1"/>
    <limit effort="169" lower="0.0" upper="2.5847" velocity="1"/>
  </joint>
  <link name="leg_link3">
    <inertial>
      <origin xyz="0.0001 0.00931 -0.02092"/>
      <mass value="4.5"/>
      <inertia ixx="0.01939794" ixy="1.798e-05" ixz="2.812e-05" iyy="0.01757571" iyz="1.732e-05" izz="0.01384547"/>
    </inertial>
    <visual>
      <geometry>
        <mesh filename="package://galbot_one_golf_description/meshes/visual/leg/leg3.glb"/>
      </geometry>
    </visual>
    <collision>
      <geometry>
        <mesh filename="package://galbot_one_golf_description/meshes/collision/leg/link3.stl"/>
      </geometry>
    </collision>
  </link>
  <joint name="leg_joint3" type="revolute">
    <origin rpy="3.141592653589793 0 3.141592653589793" xyz="0.39 0 0"/>
    <parent link="leg_link2"/>
    <child link="leg_link3"/>
    <axis xyz="0 0 1"/>
    <limit effort="84" lower="0.0" upper="2.3262" velocity="1"/>
  </joint>
  <link name="leg_link4">
    <inertial>
      <origin xyz="8e-05 -0.02006 -0.04905"/>
      <mass value="5.05"/>
      <inertia ixx="0.03451013" ixy="8.33e-06" ixz="2.101e-05" iyy="0.03294961" iyz="0.00043489" izz="0.01161759"/>
    </inertial>
    <visual>
      <geometry>
        <mesh filename="package://galbot_one_golf_description/meshes/visual/leg/leg4.glb"/>
      </geometry>
    </visual>
  </link>
  <joint name="leg_joint4" type="revolute">
    <origin rpy="-1.5707963267948966 -1.5707963267948966 0" xyz="0 0.224 0"/>
    <parent link="leg_link3"/>
    <child link="leg_link4"/>
    <axis xyz="0 0 1"/>
    <limit effort="30" lower="-1.5906" upper="1.5906" velocity="1"/>
  </joint>
  <link name="leg_link5">
    <inertial>
      <origin xyz="0 0.01247 0.0529"/>
      <mass value="1.28"/>
      <inertia ixx="0.0059985" ixy="0" ixz="0" iyy="0.0059157" iyz="0.00029352" izz="0.00345508"/>
    </inertial>
  </link>
  <joint name="leg_joint5" type="revolute">
    <origin rpy="1.5707963267948966 0 0"/>
    <parent link="leg_link4"/>
    <child link="leg_link5"/>
    <axis xyz="0 0 1"/>
    <limit effort="30" lower="-0.1645" upper="0.1645" velocity="1"/>
  </joint>
  <link name="leg_end_effector_mount_link"/>
  <joint name="leg_end_effector_mount_joint" type="fixed">
    <parent link="leg_link5"/>
    <child link="leg_end_effector_mount_link"/>
  </joint>
  <joint name="torso_joint" type="fixed">
    <parent link="leg_end_effector_mount_link"/>
    <child link="torso_base_link"/>
  </joint>
  <link name="torso_base_link">
    <inertial>
      <origin xyz="0.0053 0.1249 -0.00088"/>
      <mass value="6.83"/>
      <inertia ixx="0.12762873" ixy="0.00338332" ixz="0.00152351" iyy="0.04560482" iyz="0.0004879" izz="0.13469248"/>
    </inertial>
    <visual>
      <geometry>
        <mesh filename="package://galbot_one_golf_description/meshes/visual/torso/torso.glb"/>
      </geometry>
    </visual>
    <collision>
      <geometry>
        <mesh filename="package://galbot_one_golf_description/meshes/collision/torso.stl"/>
      </geometry>
    </collision>
  </link>
  <!-- Robot Base Link -->
  <link name="base_footprint"/>
  <joint name="base_footprint_joint" type="fixed">
    <origin xyz="0 0 0.028166"/>
    <parent link="base_footprint"/>
    <child link="base_link"/>
  </joint>
  <link name="base_link"/>
  <joint name="omni_chassis_joint" type="fixed">
    <parent link="base_link"/>
    <child link="omni_chassis_base_link"/>
  </joint>
  <link name="omni_chassis_base_link">
    <inertial>
      <origin xyz="0.02079 0.00615 0.07261"/>
      <mass value="30.15"/>
      <inertia ixx="0.3317069394" ixy="3.760583e-05" ixz="3.706221e-05" iyy="0.32081635568" iyz="1.303674e-05" izz="0.55833152838"/>
    </inertial>
    <visual>
      <geometry>
        <mesh filename="package://galbot_one_golf_description/meshes/visual/chassis/chassis.glb"/>
      </geometry>
    </visual>
    <collision>
      <origin xyz="0 0 0.11"/>
      <geometry>
        <cylinder length="0.2" radius="0.3"/>
      </geometry>
    </collision>
  </link>
  <link name="omni_chassis_leg_mount_link"/>
  <joint name="omni_chassis_leg_mount_joint" type="fixed">
    <origin xyz="0.134 0 0.1325"/>
    <parent link="omni_chassis_base_link"/>
    <child link="omni_chassis_leg_mount_link"/>
  </joint>
  <!-- 轮子链接 -->
  <link name="wheel_1">
    <inertial>
      <origin xyz="0.0026089441594678298 -1.3189703553351252e-07 2.8695680726054107e-07"/>
      <mass value="4.24803000494366"/>
      <inertia ixx="0.012235" ixy="-0.0" ixz="0.0" iyy="0.006629" iyz="0.0" izz="0.006629"/>
    </inertial>
    <visual>
      <geometry>
        <mesh filename="package://galbot_one_golf_description/meshes/visual/components/omniwheel_10.glb"/>
      </geometry>
    </visual>
    <collision name="wheel_1_collision_0">
      <origin xyz="0 0.025 0.0"/>
      <geometry>
        <sphere radius="0.08"/>
      </geometry>
    </collision>
    <collision name="wheel_1_collision_1">
      <origin xyz="0 0.02022542485937369 0.014694631307311828"/>
      <geometry>
        <sphere radius="0.08"/>
      </geometry>
    </collision>
    <collision name="wheel_1_collision_2">
      <origin xyz="0 0.007725424859373687 0.02377641290737884"/>
      <geometry>
        <sphere radius="0.08"/>
      </geometry>
    </collision>
    <collision name="wheel_1_collision_3">
      <origin xyz="0 -0.007725424859373684 0.023776412907378842"/>
      <geometry>
        <sphere radius="0.08"/>
      </geometry>
    </collision>
    <collision name="wheel_1_collision_4">
      <origin xyz="0 -0.020225424859373686 0.014694631307311832"/>
      <geometry>
        <sphere radius="0.08"/>
      </geometry>
    </collision>
    <collision name="wheel_1_collision_5">
      <origin xyz="0 -0.025 3.061616997868383e-18"/>
      <geometry>
        <sphere radius="0.08"/>
      </geometry>
    </collision>
    <collision name="wheel_1_collision_6">
      <origin xyz="0 -0.02022542485937369 -0.014694631307311827"/>
      <geometry>
        <sphere radius="0.08"/>
      </geometry>
    </collision>
    <collision name="wheel_1_collision_7">
      <origin xyz="0 -0.007725424859373689 -0.02377641290737884"/>
      <geometry>
        <sphere radius="0.08"/>
      </geometry>
    </collision>
    <collision name="wheel_1_collision_8">
      <origin xyz="0 0.007725424859373681 -0.023776412907378842"/>
      <geometry>
        <sphere radius="0.08"/>
      </geometry>
    </collision>
    <collision name="wheel_1_collision_9">
      <origin xyz="0 0.020225424859373686 -0.014694631307311835"/>
      <geometry>
        <sphere radius="0.08"/>
      </geometry>
    </collision>
  </link>
  <!-- 轮子链接 -->
  <link name="wheel_2">
    <inertial>
      <origin xyz="0.0026089441594678298 -1.3189703553351252e-07 2.8695680726054107e-07"/>
      <mass value="4.24803000494366"/>
      <inertia ixx="0.012235" ixy="-0.0" ixz="0.0" iyy="0.006629" iyz="0.0" izz="0.006629"/>
    </inertial>
    <visual>
      <geometry>
        <mesh filename="package://galbot_one_golf_description/meshes/visual/components/omniwheel_10.glb"/>
      </geometry>
    </visual>
    <collision name="wheel_2_collision_0">
      <origin xyz="0 0.025 0.0"/>
      <geometry>
        <sphere radius="0.08"/>
      </geometry>
    </collision>
    <collision name="wheel_2_collision_1">
      <origin xyz="0 0.02022542485937369 0.014694631307311828"/>
      <geometry>
        <sphere radius="0.08"/>
      </geometry>
    </collision>
    <collision name="wheel_2_collision_2">
      <origin xyz="0 0.007725424859373687 0.02377641290737884"/>
      <geometry>
        <sphere radius="0.08"/>
      </geometry>
    </collision>
    <collision name="wheel_2_collision_3">
      <origin xyz="0 -0.007725424859373684 0.023776412907378842"/>
      <geometry>
        <sphere radius="0.08"/>
      </geometry>
    </collision>
    <collision name="wheel_2_collision_4">
      <origin xyz="0 -0.020225424859373686 0.014694631307311832"/>
      <geometry>
        <sphere radius="0.08"/>
      </geometry>
    </collision>
    <collision name="wheel_2_collision_5">
      <origin xyz="0 -0.025 3.061616997868383e-18"/>
      <geometry>
        <sphere radius="0.08"/>
      </geometry>
    </collision>
    <collision name="wheel_2_collision_6">
      <origin xyz="0 -0.02022542485937369 -0.014694631307311827"/>
      <geometry>
        <sphere radius="0.08"/>
      </geometry>
    </collision>
    <collision name="wheel_2_collision_7">
      <origin xyz="0 -0.007725424859373689 -0.02377641290737884"/>
      <geometry>
        <sphere radius="0.08"/>
      </geometry>
    </collision>
    <collision name="wheel_2_collision_8">
      <origin xyz="0 0.007725424859373681 -0.023776412907378842"/>
      <geometry>
        <sphere radius="0.08"/>
      </geometry>
    </collision>
    <collision name="wheel_2_collision_9">
      <origin xyz="0 0.020225424859373686 -0.014694631307311835"/>
      <geometry>
        <sphere radius="0.08"/>
      </geometry>
    </collision>
  </link>
  <!-- 轮子链接 -->
  <link name="wheel_3">
    <inertial>
      <origin xyz="0.0026089441594678298 -1.3189703553351252e-07 2.8695680726054107e-07"/>
      <mass value="4.24803000494366"/>
      <inertia ixx="0.012235" ixy="-0.0" ixz="0.0" iyy="0.006629" iyz="0.0" izz="0.006629"/>
    </inertial>
    <visual>
      <geometry>
        <mesh filename="package://galbot_one_golf_description/meshes/visual/components/omniwheel_10.glb"/>
      </geometry>
    </visual>
    <collision name="wheel_3_collision_0">
      <origin xyz="0 0.025 0.0"/>
      <geometry>
        <sphere radius="0.08"/>
      </geometry>
    </collision>
    <collision name="wheel_3_collision_1">
      <origin xyz="0 0.02022542485937369 0.014694631307311828"/>
      <geometry>
        <sphere radius="0.08"/>
      </geometry>
    </collision>
    <collision name="wheel_3_collision_2">
      <origin xyz="0 0.007725424859373687 0.02377641290737884"/>
      <geometry>
        <sphere radius="0.08"/>
      </geometry>
    </collision>
    <collision name="wheel_3_collision_3">
      <origin xyz="0 -0.007725424859373684 0.023776412907378842"/>
      <geometry>
        <sphere radius="0.08"/>
      </geometry>
    </collision>
    <collision name="wheel_3_collision_4">
      <origin xyz="0 -0.020225424859373686 0.014694631307311832"/>
      <geometry>
        <sphere radius="0.08"/>
      </geometry>
    </collision>
    <collision name="wheel_3_collision_5">
      <origin xyz="0 -0.025 3.061616997868383e-18"/>
      <geometry>
        <sphere radius="0.08"/>
      </geometry>
    </collision>
    <collision name="wheel_3_collision_6">
      <origin xyz="0 -0.02022542485937369 -0.014694631307311827"/>
      <geometry>
        <sphere radius="0.08"/>
      </geometry>
    </collision>
    <collision name="wheel_3_collision_7">
      <origin xyz="0 -0.007725424859373689 -0.02377641290737884"/>
      <geometry>
        <sphere radius="0.08"/>
      </geometry>
    </collision>
    <collision name="wheel_3_collision_8">
      <origin xyz="0 0.007725424859373681 -0.023776412907378842"/>
      <geometry>
        <sphere radius="0.08"/>
      </geometry>
    </collision>
    <collision name="wheel_3_collision_9">
      <origin xyz="0 0.020225424859373686 -0.014694631307311835"/>
      <geometry>
        <sphere radius="0.08"/>
      </geometry>
    </collision>
  </link>
  <!-- 轮子链接 -->
  <link name="wheel_4">
    <inertial>
      <origin xyz="0.0026089441594678298 -1.3189703553351252e-07 2.8695680726054107e-07"/>
      <mass value="4.24803000494366"/>
      <inertia ixx="0.012235" ixy="-0.0" ixz="0.0" iyy="0.006629" iyz="0.0" izz="0.006629"/>
    </inertial>
    <visual>
      <geometry>
        <mesh filename="package://galbot_one_golf_description/meshes/visual/components/omniwheel_10.glb"/>
      </geometry>
    </visual>
    <collision name="wheel_4_collision_0">
      <origin xyz="0 0.025 0.0"/>
      <geometry>
        <sphere radius="0.08"/>
      </geometry>
    </collision>
    <collision name="wheel_4_collision_1">
      <origin xyz="0 0.02022542485937369 0.014694631307311828"/>
      <geometry>
        <sphere radius="0.08"/>
      </geometry>
    </collision>
    <collision name="wheel_4_collision_2">
      <origin xyz="0 0.007725424859373687 0.02377641290737884"/>
      <geometry>
        <sphere radius="0.08"/>
      </geometry>
    </collision>
    <collision name="wheel_4_collision_3">
      <origin xyz="0 -0.007725424859373684 0.023776412907378842"/>
      <geometry>
        <sphere radius="0.08"/>
      </geometry>
    </collision>
    <collision name="wheel_4_collision_4">
      <origin xyz="0 -0.020225424859373686 0.014694631307311832"/>
      <geometry>
        <sphere radius="0.08"/>
      </geometry>
    </collision>
    <collision name="wheel_4_collision_5">
      <origin xyz="0 -0.025 3.061616997868383e-18"/>
      <geometry>
        <sphere radius="0.08"/>
      </geometry>
    </collision>
    <collision name="wheel_4_collision_6">
      <origin xyz="0 -0.02022542485937369 -0.014694631307311827"/>
      <geometry>
        <sphere radius="0.08"/>
      </geometry>
    </collision>
    <collision name="wheel_4_collision_7">
      <origin xyz="0 -0.007725424859373689 -0.02377641290737884"/>
      <geometry>
        <sphere radius="0.08"/>
      </geometry>
    </collision>
    <collision name="wheel_4_collision_8">
      <origin xyz="0 0.007725424859373681 -0.023776412907378842"/>
      <geometry>
        <sphere radius="0.08"/>
      </geometry>
    </collision>
    <collision name="wheel_4_collision_9">
      <origin xyz="0 0.020225424859373686 -0.014694631307311835"/>
      <geometry>
        <sphere radius="0.08"/>
      </geometry>
    </collision>
  </link>
  <joint name="wheel1_joint" type="fixed">
    <origin rpy="0 0 -2.356194490192345" xyz="0.176493 0.176493 0.071834"/>
    <parent link="omni_chassis_base_link"/>
    <child link="wheel_1"/>
  </joint>
  <joint name="wheel2_joint" type="fixed">
    <origin rpy="0 0 -0.7853981633974483" xyz="-0.176493 0.176493 0.071834"/>
    <parent link="omni_chassis_base_link"/>
    <child link="wheel_2"/>
  </joint>
  <joint name="wheel3_joint" type="fixed">
    <origin rpy="0 0 0.7853981633974483" xyz="-0.176493 -0.176493 0.071834"/>
    <parent link="omni_chassis_base_link"/>
    <child link="wheel_3"/>
  </joint>
  <joint name="wheel4_joint" type="fixed">
    <origin rpy="0 0 2.356194490192345" xyz="0.176493 -0.176493 0.071834"/>
    <parent link="omni_chassis_base_link"/>
    <child link="wheel_4"/>
  </joint>
  <link name="chassis_lidar">
    <visual>
      <geometry>
        <mesh filename="package://galbot_one_golf_description/meshes/visual/sensors/mid360/mid360.glb"/>
      </geometry>
    </visual>
  </link>
  <joint name="chassis_lidar_joint" type="fixed">
    <parent link="omni_chassis_base_link"/>
    <child link="chassis_lidar"/>
    <origin xyz="0.235 0 0.2144"/>
  </joint>
  <link name="torso_head_mount_link"/>
  <joint name="torso_head_mount_joint" type="fixed">
    <origin rpy="-1.5707963267948966 -1.5707963267948966 0" xyz="0 0.37711 0"/>
    <parent link="torso_base_link"/>
    <child link="torso_head_mount_link"/>
    <axis/>
  </joint>
  <joint name="head_joint" type="fixed">
    <parent link="torso_head_mount_link"/>
    <child link="head_base_link"/>
  </joint>
  <link name="head_base_link">
    <inertial>
      <origin xyz="-0.00019 0.00012 -0.0832"/>
      <mass value="0.39"/>
      <inertia ixx="0.00352162" ixy="1.6e-07" ixz="6.77e-06" iyy="0.00343251" iyz="2.91e-06" izz="0.00044115"/>
    </inertial>
  </link>
  <link name="head_link1">
    <inertial>
      <origin xyz="1e-05 0.00189 -0.04337"/>
      <mass value="1.5695"/>
      <inertia ixx="0.0069002956" ixy="1.52205e-06" ixz="3.13295e-06" iyy="0.0068330036" iyz="1.009318e-05" izz="0.0011696764"/>
    </inertial>
    <visual>
      <origin rpy="0 0 0" xyz="0 0 0"/>
      <geometry>
        <mesh filename="package://galbot_one_golf_description/meshes/visual/head/head_link1.glb"/>
      </geometry>
    </visual>
    <collision>
      <origin rpy="0 0 0" xyz="0 0 0"/>
      <geometry>
        <mesh filename="package://galbot_one_golf_description/meshes/collision/head/head_link1.stl"/>
      </geometry>
    </collision>
  </link>
  <joint name="head_joint1" type="revolute">
    <parent link="head_base_link"/>
    <child link="head_link1"/>
    <axis xyz="0 0 1"/>
    <limit effort="4" lower="-1.5208" upper="1.5208" velocity="1.5"/>
  </joint>
  <link name="head_link2">
    <inertial>
      <origin xyz="0.03563 -0.03998 0.00678"/>
      <mass value="0.81"/>
      <inertia ixx="0.00399161" ixy="0.00129825" ixz="3.92e-06" iyy="0.00372602" iyz="7.75e-06" izz="0.00553062"/>
    </inertial>
    <visual>
      <origin rpy="0 0 0" xyz="0 0 0"/>
      <geometry>
        <mesh filename="package://galbot_one_golf_description/meshes/visual/head/head_link2.glb"/>
      </geometry>
    </visual>
    <collision>
      <origin rpy="0 0 0" xyz="0 0 0"/>
      <geometry>
        <mesh filename="package://galbot_one_golf_description/meshes/collision/head/head_link2.stl"/>
      </geometry>
    </collision>
  </link>
  <joint name="head_joint2" type="revolute">
    <origin rpy="-1.5707963267948966 0 0"/>
    <parent link="head_link1"/>
    <child link="head_link2"/>
    <axis xyz="0 0 1"/>
    <limit effort="4" lower="-0.2143461" upper="0.4935988" velocity="1.5"/>
  </joint>
  <link name="head_end_effector_mount_link"/>
  <joint name="head_end_effector_mount_joint" type="fixed">
    <parent link="head_link2"/>
    <child link="head_end_effector_mount_link"/>
    <axis/>
  </joint>
  <!-- Left Arm Mount -->
  <link name="torso_left_arm_mount_link"/>
  <joint name="torso_left_arm_mount_joint" type="fixed">
    <origin rpy="0 1.5707963267948966 0" xyz="0.20843 0.172 0"/>
    <parent link="torso_base_link"/>
    <child link="torso_left_arm_mount_link"/>
    <axis/>
  </joint>
  <!-- Right Arm Mount -->
  <link name="torso_right_arm_mount_link"/>
  <joint name="torso_right_arm_mount_joint" type="fixed">
    <origin rpy="3.141592653589793 1.5707963267948966 0" xyz="-0.20843 0.172 0"/>
    <parent link="torso_base_link"/>
    <child link="torso_right_arm_mount_link"/>
    <axis/>
  </joint>
  <joint name="right_arm_joint" type="fixed">
    <origin rpy="0 0 0" xyz="0 0 0"/>
    <parent link="torso_right_arm_mount_link"/>
    <child link="right_arm_base_link"/>
  </joint>
  <link name="right_arm_base_link">
    <inertial>
      <origin xyz="0.0 0.0 -0.10506"/>
      <mass value="0.92"/>
      <inertia ixx="0.01075595" ixy="9e-08" ixz="4.1e-07" iyy="0.01077842" iyz="1.896e-05" izz="0.0007042000000000001"/>
    </inertial>
  </link>
  <link name="right_arm_link1">
    <inertial>
      <origin xyz="0.0 -0.0009699999999999999 -0.015390000000000001"/>
      <mass value="1.6"/>
      <inertia ixx="0.00332981" ixy="1.8920000000000002e-05" ixz="6.9e-07" iyy="0.00339121" iyz="2.9760000000000003e-05" izz="0.0016524"/>
    </inertial>
    <visual>
      <geometry>
        <mesh filename="package://galbot_one_golf_description/meshes/visual/arm/link1.glb" scale="1 -1 1"/>
      </geometry>
    </visual>
    <collision>
      <geometry>
        <mesh filename="package://galbot_one_golf_description/meshes/collision/arm/link1.stl" scale="1 -1 1"/>
      </geometry>
    </collision>
  </link>
  <joint name="right_arm_joint1" type="revolute">
    <origin rpy="0 0 -0.523598775598286"/>
    <parent link="right_arm_base_link"/>
    <child link="right_arm_link1"/>
    <axis xyz="0 0 1"/>
    <limit acceleration="2" effort="60" jerk="12" lower="-3.00432619" upper="3.00432619" velocity="1.5"/>
  </joint>
  <link name="right_arm_link2">
    <inertial>
      <origin xyz="0.0 -0.09558 0.010150000000000001"/>
      <mass value="1.43"/>
      <inertia ixx="0.01937881" ixy="2.0000000000000002e-07" ixz="1.2e-07" iyy="0.0015791400000000001" iyz="0.00019578" izz="0.018951810000000003"/>
    </inertial>
    <visual>
      <geometry>
        <mesh filename="package://galbot_one_golf_description/meshes/visual/arm/link2_right.glb"/>
      </geometry>
    </visual>
    <collision>
      <geometry>
        <mesh filename="package://galbot_one_golf_description/meshes/collision/arm/link2.stl" scale="1 -1 1"/>
      </geometry>
    </collision>
  </link>
  <joint name="right_arm_joint2" type="revolute">
    <origin rpy="-1.5707963267949 0 3.14159265358979"/>
    <parent link="right_arm_link1"/>
    <child link="right_arm_link2"/>
    <axis xyz="0 0 1"/>
    <limit acceleration="2" effort="60" jerk="12" lower="-1.608062789" upper="1.608062789" velocity="1.5"/>
  </joint>
  <link name="right_arm_link3">
    <inertial>
      <origin xyz="0.0 -0.00088 -0.04936"/>
      <mass value="1.43"/>
      <inertia ixx="0.01187457" ixy="1.5e-07" ixz="8.5e-07" iyy="0.01178759" iyz="0.00010048" izz="0.0013715"/>
    </inertial>
    <visual>
      <geometry>
        <mesh filename="package://galbot_one_golf_description/meshes/visual/arm/link3.glb" scale="1 -1 1"/>
      </geometry>
    </visual>
    <collision>
      <geometry>
        <mesh filename="package://galbot_one_golf_description/meshes/collision/arm/link3.stl" scale="1 -1 1"/>
      </geometry>
    </collision>
  </link>
  <joint name="right_arm_joint3" type="revolute">
    <origin rpy="-1.5707963267949 1.04719755119629 -3.14159265358979" xyz="0 -0.35 0"/>
    <parent link="right_arm_link2"/>
    <child link="right_arm_link3"/>
    <axis xyz="0 0 1"/>
    <limit acceleration="2" effort="30" jerk="12" lower="-2.916972222" upper="2.916972222" velocity="1.5"/>
  </joint>
  <link name="right_arm_link4">
    <inertial>
      <origin xyz="0.0 -0.05614 0.019170000000000003"/>
      <mass value="1.1"/>
      <inertia ixx="0.00701388" ixy="3.2e-07" ixz="1.16e-06" iyy="0.00161854" iyz="0.00033944" izz="0.0065011999999999995"/>
    </inertial>
    <visual>
      <geometry>
        <mesh filename="package://galbot_one_golf_description/meshes/visual/arm/link4.glb" scale="1 -1 1"/>
      </geometry>
    </visual>
    <collision>
      <geometry>
        <mesh filename="package://galbot_one_golf_description/meshes/collision/arm/link4.stl" scale="1 -1 1"/>
      </geometry>
    </collision>
  </link>
  <joint name="right_arm_joint4" type="revolute">
    <origin rpy="-1.57079632679459 0 3.14159265358979"/>
    <parent link="right_arm_link3"/>
    <child link="right_arm_link4"/>
    <axis xyz="0 0 1"/>
    <limit acceleration="2" effort="30" jerk="12" lower="-1.869862177" upper="2.5679938779914946" velocity="1.5"/>
  </joint>
  <link name="right_arm_link5">
    <inertial>
      <origin xyz="0.00044 0.0016899999999999999 -0.13306"/>
      <mass value="1.15"/>
      <inertia ixx="0.025809930000000002" ixy="1.98e-05" ixz="5.605e-05" iyy="0.02530313" iyz="0.00020931999999999998" izz="0.00115848"/>
    </inertial>
    <visual>
      <geometry>
        <mesh filename="package://galbot_one_golf_description/meshes/visual/arm/link5.glb"/>
      </geometry>
    </visual>
    <collision>
      <geometry>
        <mesh filename="package://galbot_one_golf_description/meshes/collision/arm/link5.stl"/>
      </geometry>
    </collision>
  </link>
  <joint name="right_arm_joint5" type="revolute">
    <origin rpy="-1.5707963267949 0 3.1415926535898" xyz="0 -0.36 0"/>
    <parent link="right_arm_link4"/>
    <child link="right_arm_link5"/>
    <axis xyz="0 0 1"/>
    <limit acceleration="2" effort="10" jerk="12" lower="-2.916972222" upper="2.916972222" velocity="1.5"/>
  </joint>
  <link name="right_arm_link6">
    <inertial>
      <origin xyz="-0.00088 0.0072699999999999996 -0.00011999999999999999"/>
      <mass value="0.47"/>
      <inertia ixx="0.00027557" ixy="7.6e-07" ixz="1.44e-06" iyy="0.00028977999999999995" iyz="2.25e-06" izz="0.00029684"/>
    </inertial>
    <visual>
      <geometry>
        <mesh filename="package://galbot_one_golf_description/meshes/visual/arm/link6.glb" scale="1 -1 1"/>
      </geometry>
    </visual>
    <collision>
      <geometry>
        <mesh filename="package://galbot_one_golf_description/meshes/collision/arm/link6.stl" scale="1 -1 1"/>
      </geometry>
    </collision>
  </link>
  <joint name="right_arm_joint6" type="revolute">
    <origin rpy="1.5707963267949 1.5707963267949 0"/>
    <parent link="right_arm_link5"/>
    <child link="right_arm_link6"/>
    <axis xyz="0 0 1"/>
    <limit acceleration="2" effort="10" jerk="12" lower="-0.7353981633974483" upper="0.8226646259971648" velocity="1.5"/>
  </joint>
  <link name="right_arm_link7">
    <inertial>
      <origin xyz="-0.05751 0.00684 0.011869999999999999"/>
      <mass value="0.8"/>
      <inertia ixx="0.00117613" ixy="0.00033793" ixz="0.0001662" iyy="0.00423935" iyz="8.589999999999999e-06" izz="0.00417642"/>
    </inertial>
    <visual>
      <geometry>
        <mesh filename="package://galbot_one_golf_description/meshes/visual/arm/link7.glb" scale="1 -1 1"/>
      </geometry>
    </visual>
    <collision>
      <geometry>
        <mesh filename="package://galbot_one_golf_description/meshes/collision/arm/link7.stl" scale="1 -1 1"/>
      </geometry>
    </collision>
  </link>
  <joint name="right_arm_joint7" type="revolute">
    <origin rpy="-1.5707963267949 0 0"/>
    <parent link="right_arm_link6"/>
    <child link="right_arm_link7"/>
    <axis xyz="0 0 1"/>
    <limit acceleration="2" effort="10" jerk="12" lower="-1.538202778" upper="1.538202778" velocity="1.5"/>
  </joint>
  <link name="right_arm_end_effector_mount_link">
    <inertial>
      <origin xyz="0 0 0"/>
      <mass value="0"/>
      <inertia ixx="0" ixy="0" ixz="0" iyy="0" iyz="0" izz="0"/>
    </inertial>
  </link>
  <joint name="right_arm_end_effector_mount_joint" type="fixed">
    <origin rpy="3.141592653589793 0 3.141592653589793" xyz="-0.10926 0 0"/>
    <parent link="right_arm_link7"/>
    <child link="right_arm_end_effector_mount_link"/>
    <axis xyz="0 0 0"/>
  </joint>
  <joint name="right_arm_camera_stand_joint" type="fixed">
    <parent link="right_arm_link7"/>
    <child link="right_arm_wrist_camera_stand"/>
  </joint>
  <link name="right_arm_wrist_camera_stand">
    <inertial>
      <origin xyz="-0.0621229724155358 -0.0628379837355285 -0.00140310958315455"/>
      <mass value="0.0492751941348016"/>
      <inertia ixx="3.66069470547417E-05" ixy="-3.55284385731841E-07" ixz="3.8533182318026E-07" iyy="3.08593710158624E-05" iyz="-3.07292981503681E-07" izz="8.80145863410975E-06"/>
    </inertial>
    <visual>
      <geometry>
        <mesh filename="package://galbot_one_golf_description/meshes/visual/arm/d405_stand.glb"/>
      </geometry>
    </visual>
    <collision>
      <geometry>
        <mesh filename="package://galbot_one_golf_description/meshes/collision/d405.stl"/>
      </geometry>
    </collision>
  </link>
  <joint name="right_arm_camera_joint" type="fixed">
    <origin rpy="0 1.4807963267948965 3.141592653589793" xyz="-0.0822 0 -0.06842"/>
    <parent link="right_arm_wrist_camera_stand"/>
    <child link="right_wrist_camera_link"/>
  </joint>
  <link name="right_wrist_camera_link">
    <visual>
      <geometry>
        <mesh filename="package://galbot_one_golf_description/meshes/visual/sensors/realsense/d405.glb"/>
      </geometry>
    </visual>
  </link>
  <joint name="right_gripper_mount_joint" type="fixed">
    <origin rpy="1.5707963267948966 0 0" xyz="0 0 0"/>
    <parent link="right_arm_end_effector_mount_link"/>
    <child link="right_gripper_flange_link"/>
    <axis xyz="0 0 0"/>
  </joint>
  <link name="right_gripper_flange_link">
    <inertial>
      <origin xyz="0.0030662 -1.4019E-18 3.383E-18"/>
      <mass value="0.031005"/>
      <inertia ixx="2.2585E-05" ixy="-2.0366E-21" ixz="-3.7461E-22" iyy="1.141E-05" iyz="-7.8518E-23" izz="1.141E-05"/>
    </inertial>
    <visual>
      <geometry>
        <mesh filename="package://galbot_one_golf_description/meshes/visual/end_effectors/galbot_gripper/flange.glb"/>
      </geometry>
    </visual>
  </link>
  <joint name="right_gripper_base_joint" type="fixed">
    <origin xyz="0.0065 0 0"/>
    <parent link="right_gripper_flange_link"/>
    <child link="right_gripper_base_link"/>
  </joint>
  <link name="right_gripper_base_link">
    <inertial>
      <origin xyz="0.037051 -6.4001E-05 6.4706E-05"/>
      <mass value="0.061747"/>
      <inertia ixx="2.5813E-05" ixy="4.7224E-08" ixz="-3.9403E-11" iyy="7.2859E-05" iyz="-2.962E-10" izz="5.7173E-05"/>
    </inertial>
    <visual>
      <geometry>
        <mesh filename="package://galbot_one_golf_description/meshes/visual/end_effectors/galbot_gripper/base_link.glb"/>
      </geometry>
    </visual>
    <collision>
      <geometry>
        <mesh filename="package://galbot_one_golf_description/meshes/collision/end_effectors/galbot_gripper/base_link.stl"/>
      </geometry>
    </collision>
  </link>
  <link name="right_gripper_l_knuckle_link">
    <inertial>
      <origin xyz="0.024101 0 0"/>
      <mass value="0.0070682"/>
      <inertia ixx="9.2131e-08" ixy="0" ixz="0" iyy="1.559e-06" iyz="0" izz="1.4931e-06"/>
    </inertial>
    <visual>
      <geometry>
        <mesh filename="package://galbot_one_golf_description/meshes/visual/end_effectors/galbot_gripper/link1.glb"/>
      </geometry>
    </visual>
    <collision>
      <geometry>
        <mesh filename="package://galbot_one_golf_description/meshes/collision/end_effectors/galbot_gripper/link_1.stl"/>
      </geometry>
    </collision>
  </link>
  <link name="right_gripper_l_inner_knuckle_link">
    <inertial>
      <origin xyz="0.023769 0 0"/>
      <mass value="0.007802"/>
      <inertia ixx="1.044e-07" ixy="0" ixz="0" iyy="1.6385e-06" iyz="0" izz="1.566e-06"/>
    </inertial>
    <visual>
      <geometry>
        <mesh filename="package://galbot_one_golf_description/meshes/visual/end_effectors/galbot_gripper/link2.glb"/>
      </geometry>
    </visual>
    <collision>
      <geometry>
        <mesh filename="package://galbot_one_golf_description/meshes/collision/end_effectors/galbot_gripper/link_2.stl"/>
      </geometry>
    </collision>
  </link>
  <link name="right_gripper_l_finger_link">
    <inertial>
      <origin xyz="0.016809 0.0019094 0"/>
      <mass value="0.015957"/>
      <inertia ixx="5.5426e-07" ixy="0" ixz="0" iyy="1.8538e-06" iyz="0" izz="1.5262e-06"/>
    </inertial>
    <visual>
      <geometry>
        <mesh filename="package://galbot_one_golf_description/meshes/visual/end_effectors/galbot_gripper/link3.glb"/>
      </geometry>
    </visual>
    <collision>
      <geometry>
        <mesh filename="package://galbot_one_golf_description/meshes/collision/end_effectors/galbot_gripper/link_3.stl"/>
      </geometry>
    </collision>
  </link>
  <link name="right_gripper_r_knuckle_link">
    <inertial>
      <origin xyz="0.024101 0 0"/>
      <mass value="0.0070682"/>
      <inertia ixx="9.2131e-08" ixy="0" ixz="0" iyy="1.559e-06" iyz="0" izz="1.4931e-06"/>
    </inertial>
    <visual>
      <geometry>
        <mesh filename="package://galbot_one_golf_description/meshes/visual/end_effectors/galbot_gripper/link1.glb"/>
      </geometry>
    </visual>
    <collision>
      <geometry>
        <mesh filename="package://galbot_one_golf_description/meshes/collision/end_effectors/galbot_gripper/link_1.stl"/>
      </geometry>
    </collision>
  </link>
  <link name="right_gripper_r_inner_knuckle_link">
    <inertial>
      <origin xyz="0.023769 0 0"/>
      <mass value="0.007802"/>
      <inertia ixx="1.044e-07" ixy="0" ixz="0" iyy="1.6385e-06" iyz="0" izz="1.566e-06"/>
    </inertial>
    <visual>
      <geometry>
        <mesh filename="package://galbot_one_golf_description/meshes/visual/end_effectors/galbot_gripper/link2.glb"/>
      </geometry>
    </visual>
    <collision>
      <geometry>
        <mesh filename="package://galbot_one_golf_description/meshes/collision/end_effectors/galbot_gripper/link_2.stl"/>
      </geometry>
    </collision>
  </link>
  <link name="right_gripper_r_finger_link">
    <inertial>
      <origin xyz="0.016809 -0.0019094 0"/>
      <mass value="0.015957"/>
      <inertia ixx="5.5426e-07" ixy="0" ixz="0" iyy="1.8538e-06" iyz="0" izz="1.5262e-06"/>
    </inertial>
    <visual>
      <geometry>
        <mesh filename="package://galbot_one_golf_description/meshes/visual/end_effectors/galbot_gripper/link3.glb" scale="1 -1 1"/>
      </geometry>
    </visual>
    <collision>
      <geometry>
        <mesh filename="package://galbot_one_golf_description/meshes/collision/end_effectors/galbot_gripper/link_3.stl" scale="1 -1 1"/>
      </geometry>
    </collision>
  </link>
  <joint name="right_gripper_joint" type="revolute">
    <parent link="right_gripper_base_link"/>
    <child link="right_gripper_r_knuckle_link"/>
    <origin rpy="1.5707963267948966 -1.2465 0" xyz="0.0745 0 0.0385"/>
    <axis xyz="0 0 -1"/>
    <limit effort="50" lower="0.0" upper="1.703" velocity="0.5"/>
  </joint>
  <joint name="right_gripper_r_inner_knuckle_joint" type="revolute">
    <parent link="right_gripper_base_link"/>
    <child link="right_gripper_r_inner_knuckle_link"/>
    <origin rpy="1.5707963267948966 -1.2465 0" xyz="0.079 0 0.026"/>
    <axis xyz="0 0 1"/>
    <limit effort="1000" lower="-3.13" upper="3.13" velocity="2.0"/>
    <mimic joint="right_gripper_joint" multiplier="-1"/>
  </joint>
  <joint name="right_gripper_r_finger_joint" type="revolute">
    <parent link="right_gripper_r_inner_knuckle_link"/>
    <child link="right_gripper_r_finger_link"/>
    <origin rpy="0 0 -1.2465" xyz="0.045 0 0"/>
    <axis xyz="0 0 1"/>
    <limit effort="1000" lower="-3.13" upper="3.13" velocity="2.0"/>
    <mimic joint="right_gripper_joint" multiplier="1"/>
  </joint>
  <joint name="right_gripper_l_knuckle_joint" type="revolute">
    <parent link="right_gripper_base_link"/>
    <child link="right_gripper_l_knuckle_link"/>
    <origin rpy="1.5707963267948966 1.2465 0" xyz="0.0745 0 -0.0385"/>
    <axis xyz="0 0 1"/>
    <limit effort="50" lower="-3.13" upper="3.13" velocity="0.5"/>
    <mimic joint="right_gripper_joint" multiplier="1"/>
  </joint>
  <joint name="right_gripper_l_inner_knuckle_joint" type="revolute">
    <parent link="right_gripper_base_link"/>
    <child link="right_gripper_l_inner_knuckle_link"/>
    <origin rpy="1.5707963267948966 1.2465 0" xyz="0.079 0 -0.026"/>
    <axis xyz="0 0 1"/>
    <limit effort="1000" lower="-3.13" upper="3.13" velocity="2.0"/>
    <mimic joint="right_gripper_joint" multiplier="1"/>
  </joint>
  <joint name="right_gripper_l_finger_joint" type="revolute">
    <parent link="right_gripper_l_inner_knuckle_link"/>
    <child link="right_gripper_l_finger_link"/>
    <origin rpy="0 0 1.2465" xyz="0.045 0 0"/>
    <axis xyz="0 0 1"/>
    <limit effort="1000" lower="-3.13" upper="3.13" velocity="2.0"/>
    <mimic joint="right_gripper_joint" multiplier="-1"/>
  </joint>
  <link name="right_gripper_tcp_link"/>
  <joint name="right_gripper_tcp_joint" type="fixed">
    <parent link="right_gripper_base_link"/>
    <child link="right_gripper_tcp_link"/>
    <origin rpy="1.5707963267948966 0 0" xyz="0.13996 0 0"/>
  </joint>
  <joint name="left_arm_joint" type="fixed">
    <origin rpy="0 0 0" xyz="0 0 0"/>
    <parent link="torso_left_arm_mount_link"/>
    <child link="left_arm_base_link"/>
  </joint>
  <link name="left_arm_base_link">
    <inertial>
      <origin xyz="0.0 0.0 -0.10506"/>
      <mass value="0.92"/>
      <inertia ixx="0.01075595" ixy="9e-08" ixz="4.1e-07" iyy="0.01077842" iyz="1.896e-05" izz="0.0007042000000000001"/>
    </inertial>
  </link>
  <link name="left_arm_link1">
    <inertial>
      <origin xyz="0.0 0.0009699999999999999 -0.015390000000000001"/>
      <mass value="1.6"/>
      <inertia ixx="0.00332981" ixy="1.8920000000000002e-05" ixz="6.9e-07" iyy="0.00339121" iyz="2.9760000000000003e-05" izz="0.0016524"/>
    </inertial>
    <visual>
      <geometry>
        <mesh filename="package://galbot_one_golf_description/meshes/visual/arm/link1.glb" scale="1 1 1"/>
      </geometry>
    </visual>
    <collision>
      <geometry>
        <mesh filename="package://galbot_one_golf_description/meshes/collision/arm/link1.stl" scale="1 1 1"/>
      </geometry>
    </collision>
  </link>
  <joint name="left_arm_joint1" type="revolute">
    <origin rpy="0 0 0.523598775598286"/>
    <parent link="left_arm_base_link"/>
    <child link="left_arm_link1"/>
    <axis xyz="0 0 1"/>
    <limit acceleration="2" effort="60" jerk="12" lower="-3.00432619" upper="3.00432619" velocity="1.5"/>
  </joint>
  <link name="left_arm_link2">
    <inertial>
      <origin xyz="0.0 0.09558 0.010150000000000001"/>
      <mass value="1.43"/>
      <inertia ixx="0.01937881" ixy="2.0000000000000002e-07" ixz="1.2e-07" iyy="0.0015791400000000001" iyz="0.00019578" izz="0.018951810000000003"/>
    </inertial>
    <visual>
      <geometry>
        <mesh filename="package://galbot_one_golf_description/meshes/visual/arm/link2.glb"/>
      </geometry>
    </visual>
    <collision>
      <geometry>
        <mesh filename="package://galbot_one_golf_description/meshes/collision/arm/link2.stl" scale="1 1 1"/>
      </geometry>
    </collision>
  </link>
  <joint name="left_arm_joint2" type="revolute">
    <origin rpy="1.5707963267949 0 3.14159265358979"/>
    <parent link="left_arm_link1"/>
    <child link="left_arm_link2"/>
    <axis xyz="0 0 1"/>
    <limit acceleration="2" effort="60" jerk="12" lower="-1.608062789" upper="1.608062789" velocity="1.5"/>
  </joint>
  <link name="left_arm_link3">
    <inertial>
      <origin xyz="0.0 0.00088 -0.04936"/>
      <mass value="1.43"/>
      <inertia ixx="0.01187457" ixy="1.5e-07" ixz="8.5e-07" iyy="0.01178759" iyz="0.00010048" izz="0.0013715"/>
    </inertial>
    <visual>
      <geometry>
        <mesh filename="package://galbot_one_golf_description/meshes/visual/arm/link3.glb" scale="1 1 1"/>
      </geometry>
    </visual>
    <collision>
      <geometry>
        <mesh filename="package://galbot_one_golf_description/meshes/collision/arm/link3.stl" scale="1 1 1"/>
      </geometry>
    </collision>
  </link>
  <joint name="left_arm_joint3" type="revolute">
    <origin rpy="1.5707963267949 1.04719755119629 -3.14159265358979" xyz="0 0.35 0"/>
    <parent link="left_arm_link2"/>
    <child link="left_arm_link3"/>
    <axis xyz="0 0 1"/>
    <limit acceleration="2" effort="30" jerk="12" lower="-2.916972222" upper="2.916972222" velocity="1.5"/>
  </joint>
  <link name="left_arm_link4">
    <inertial>
      <origin xyz="0.0 0.05614 0.019170000000000003"/>
      <mass value="1.1"/>
      <inertia ixx="0.00701388" ixy="3.2e-07" ixz="1.16e-06" iyy="0.00161854" iyz="0.00033944" izz="0.0065011999999999995"/>
    </inertial>
    <visual>
      <geometry>
        <mesh filename="package://galbot_one_golf_description/meshes/visual/arm/link4.glb" scale="1 1 1"/>
      </geometry>
    </visual>
    <collision>
      <geometry>
        <mesh filename="package://galbot_one_golf_description/meshes/collision/arm/link4.stl" scale="1 1 1"/>
      </geometry>
    </collision>
  </link>
  <joint name="left_arm_joint4" type="revolute">
    <origin rpy="1.57079632679459 0 3.14159265358979"/>
    <parent link="left_arm_link3"/>
    <child link="left_arm_link4"/>
    <axis xyz="0 0 1"/>
    <limit acceleration="2" effort="30" jerk="12" lower="-2.5679938779914946" upper="1.869862177" velocity="1.5"/>
  </joint>
  <link name="left_arm_link5">
    <inertial>
      <origin xyz="0.00044 0.0016899999999999999 -0.13306"/>
      <mass value="1.15"/>
      <inertia ixx="0.025809930000000002" ixy="1.98e-05" ixz="5.605e-05" iyy="0.02530313" iyz="0.00020931999999999998" izz="0.00115848"/>
    </inertial>
    <visual>
      <geometry>
        <mesh filename="package://galbot_one_golf_description/meshes/visual/arm/link5.glb"/>
      </geometry>
    </visual>
    <collision>
      <geometry>
        <mesh filename="package://galbot_one_golf_description/meshes/collision/arm/link5.stl"/>
      </geometry>
    </collision>
  </link>
  <joint name="left_arm_joint5" type="revolute">
    <origin rpy="-1.5707963267949 0 0.0" xyz="0 0.36 0"/>
    <parent link="left_arm_link4"/>
    <child link="left_arm_link5"/>
    <axis xyz="0 0 1"/>
    <limit acceleration="2" effort="10" jerk="12" lower="-2.916972222" upper="2.916972222" velocity="1.5"/>
  </joint>
  <link name="left_arm_link6">
    <inertial>
      <origin xyz="-0.00088 -0.0072699999999999996 -0.00011999999999999999"/>
      <mass value="0.47"/>
      <inertia ixx="0.00027557" ixy="7.6e-07" ixz="1.44e-06" iyy="0.00028977999999999995" iyz="2.25e-06" izz="0.00029684"/>
    </inertial>
    <visual>
      <geometry>
        <mesh filename="package://galbot_one_golf_description/meshes/visual/arm/link6.glb" scale="1 1 1"/>
      </geometry>
    </visual>
    <collision>
      <geometry>
        <mesh filename="package://galbot_one_golf_description/meshes/collision/arm/link6.stl" scale="1 1 1"/>
      </geometry>
    </collision>
  </link>
  <joint name="left_arm_joint6" type="revolute">
    <origin rpy="1.5707963267949 1.5707963267949 0"/>
    <parent link="left_arm_link5"/>
    <child link="left_arm_link6"/>
    <axis xyz="0 0 1"/>
    <limit acceleration="2" effort="10" jerk="12" lower="-0.8226646259971648" upper="0.7353981633974483" velocity="1.5"/>
  </joint>
  <link name="left_arm_link7">
    <inertial>
      <origin xyz="-0.05751 -0.00684 0.011869999999999999"/>
      <mass value="0.8"/>
      <inertia ixx="0.00117613" ixy="0.00033793" ixz="0.0001662" iyy="0.00423935" iyz="8.589999999999999e-06" izz="0.00417642"/>
    </inertial>
    <visual>
      <geometry>
        <mesh filename="package://galbot_one_golf_description/meshes/visual/arm/link7.glb" scale="1 1 1"/>
      </geometry>
    </visual>
    <collision>
      <geometry>
        <mesh filename="package://galbot_one_golf_description/meshes/collision/arm/link7.stl" scale="1 1 1"/>
      </geometry>
    </collision>
  </link>
  <joint name="left_arm_joint7" type="revolute">
    <origin rpy="1.5707963267949 0 0"/>
    <parent link="left_arm_link6"/>
    <child link="left_arm_link7"/>
    <axis xyz="0 0 1"/>
    <limit acceleration="2" effort="10" jerk="12" lower="-1.538202778" upper="1.538202778" velocity="1.5"/>
  </joint>
  <link name="left_arm_end_effector_mount_link">
    <inertial>
      <origin xyz="0 0 0"/>
      <mass value="0"/>
      <inertia ixx="0" ixy="0" ixz="0" iyy="0" iyz="0" izz="0"/>
    </inertial>
  </link>
  <joint name="left_arm_end_effector_mount_joint" type="fixed">
    <origin rpy="3.141592653589793 0 3.141592653589793" xyz="-0.10926 0 0"/>
    <parent link="left_arm_link7"/>
    <child link="left_arm_end_effector_mount_link"/>
    <axis xyz="0 0 0"/>
  </joint>
  <joint name="left_arm_camera_stand_joint" type="fixed">
    <parent link="left_arm_link7"/>
    <child link="left_arm_wrist_camera_stand"/>
  </joint>
  <link name="left_arm_wrist_camera_stand">
    <inertial>
      <origin xyz="-0.0621229724155358 -0.0628379837355285 -0.00140310958315455"/>
      <mass value="0.0492751941348016"/>
      <inertia ixx="3.66069470547417E-05" ixy="-3.55284385731841E-07" ixz="3.8533182318026E-07" iyy="3.08593710158624E-05" iyz="-3.07292981503681E-07" izz="8.80145863410975E-06"/>
    </inertial>
    <visual>
      <geometry>
        <mesh filename="package://galbot_one_golf_description/meshes/visual/arm/d405_stand.glb"/>
      </geometry>
    </visual>
    <collision>
      <geometry>
        <mesh filename="package://galbot_one_golf_description/meshes/collision/d405.stl"/>
      </geometry>
    </collision>
  </link>
  <joint name="left_arm_camera_joint" type="fixed">
    <origin rpy="0 1.4807963267948965 3.141592653589793" xyz="-0.0822 0 -0.06842"/>
    <parent link="left_arm_wrist_camera_stand"/>
    <child link="left_wrist_camera_link"/>
  </joint>
  <link name="left_wrist_camera_link">
    <visual>
      <geometry>
        <mesh filename="package://galbot_one_golf_description/meshes/visual/sensors/realsense/d405.glb"/>
      </geometry>
    </visual>
  </link>
  <joint name="left_gripper_mount_joint" type="fixed">
    <origin rpy="1.5707963267948966 0 0" xyz="0 0 0"/>
    <parent link="left_arm_end_effector_mount_link"/>
    <child link="left_gripper_flange_link"/>
    <axis xyz="0 0 0"/>
  </joint>
  <link name="left_gripper_flange_link">
    <inertial>
      <origin xyz="0.0030662 -1.4019E-18 3.383E-18"/>
      <mass value="0.031005"/>
      <inertia ixx="2.2585E-05" ixy="-2.0366E-21" ixz="-3.7461E-22" iyy="1.141E-05" iyz="-7.8518E-23" izz="1.141E-05"/>
    </inertial>
    <visual>
      <geometry>
        <mesh filename="package://galbot_one_golf_description/meshes/visual/end_effectors/galbot_gripper/flange.glb"/>
      </geometry>
    </visual>
  </link>
  <joint name="left_gripper_base_joint" type="fixed">
    <origin xyz="0.0065 0 0"/>
    <parent link="left_gripper_flange_link"/>
    <child link="left_gripper_base_link"/>
  </joint>
  <link name="left_gripper_base_link">
    <inertial>
      <origin xyz="0.037051 -6.4001E-05 6.4706E-05"/>
      <mass value="0.061747"/>
      <inertia ixx="2.5813E-05" ixy="4.7224E-08" ixz="-3.9403E-11" iyy="7.2859E-05" iyz="-2.962E-10" izz="5.7173E-05"/>
    </inertial>
    <visual>
      <geometry>
        <mesh filename="package://galbot_one_golf_description/meshes/visual/end_effectors/galbot_gripper/base_link.glb"/>
      </geometry>
    </visual>
    <collision>
      <geometry>
        <mesh filename="package://galbot_one_golf_description/meshes/collision/end_effectors/galbot_gripper/base_link.stl"/>
      </geometry>
    </collision>
  </link>
  <link name="left_gripper_l_knuckle_link">
    <inertial>
      <origin xyz="0.024101 0 0"/>
      <mass value="0.0070682"/>
      <inertia ixx="9.2131e-08" ixy="0" ixz="0" iyy="1.559e-06" iyz="0" izz="1.4931e-06"/>
    </inertial>
    <visual>
      <geometry>
        <mesh filename="package://galbot_one_golf_description/meshes/visual/end_effectors/galbot_gripper/link1.glb"/>
      </geometry>
    </visual>
    <collision>
      <geometry>
        <mesh filename="package://galbot_one_golf_description/meshes/collision/end_effectors/galbot_gripper/link_1.stl"/>
      </geometry>
    </collision>
  </link>
  <link name="left_gripper_l_inner_knuckle_link">
    <inertial>
      <origin xyz="0.023769 0 0"/>
      <mass value="0.007802"/>
      <inertia ixx="1.044e-07" ixy="0" ixz="0" iyy="1.6385e-06" iyz="0" izz="1.566e-06"/>
    </inertial>
    <visual>
      <geometry>
        <mesh filename="package://galbot_one_golf_description/meshes/visual/end_effectors/galbot_gripper/link2.glb"/>
      </geometry>
    </visual>
    <collision>
      <geometry>
        <mesh filename="package://galbot_one_golf_description/meshes/collision/end_effectors/galbot_gripper/link_2.stl"/>
      </geometry>
    </collision>
  </link>
  <link name="left_gripper_l_finger_link">
    <inertial>
      <origin xyz="0.016809 0.0019094 0"/>
      <mass value="0.015957"/>
      <inertia ixx="5.5426e-07" ixy="0" ixz="0" iyy="1.8538e-06" iyz="0" izz="1.5262e-06"/>
    </inertial>
    <visual>
      <geometry>
        <mesh filename="package://galbot_one_golf_description/meshes/visual/end_effectors/galbot_gripper/link3.glb"/>
      </geometry>
    </visual>
    <collision>
      <geometry>
        <mesh filename="package://galbot_one_golf_description/meshes/collision/end_effectors/galbot_gripper/link_3.stl"/>
      </geometry>
    </collision>
  </link>
  <link name="left_gripper_r_knuckle_link">
    <inertial>
      <origin xyz="0.024101 0 0"/>
      <mass value="0.0070682"/>
      <inertia ixx="9.2131e-08" ixy="0" ixz="0" iyy="1.559e-06" iyz="0" izz="1.4931e-06"/>
    </inertial>
    <visual>
      <geometry>
        <mesh filename="package://galbot_one_golf_description/meshes/visual/end_effectors/galbot_gripper/link1.glb"/>
      </geometry>
    </visual>
    <collision>
      <geometry>
        <mesh filename="package://galbot_one_golf_description/meshes/collision/end_effectors/galbot_gripper/link_1.stl"/>
      </geometry>
    </collision>
  </link>
  <link name="left_gripper_r_inner_knuckle_link">
    <inertial>
      <origin xyz="0.023769 0 0"/>
      <mass value="0.007802"/>
      <inertia ixx="1.044e-07" ixy="0" ixz="0" iyy="1.6385e-06" iyz="0" izz="1.566e-06"/>
    </inertial>
    <visual>
      <geometry>
        <mesh filename="package://galbot_one_golf_description/meshes/visual/end_effectors/galbot_gripper/link2.glb"/>
      </geometry>
    </visual>
    <collision>
      <geometry>
        <mesh filename="package://galbot_one_golf_description/meshes/collision/end_effectors/galbot_gripper/link_2.stl"/>
      </geometry>
    </collision>
  </link>
  <link name="left_gripper_r_finger_link">
    <inertial>
      <origin xyz="0.016809 -0.0019094 0"/>
      <mass value="0.015957"/>
      <inertia ixx="5.5426e-07" ixy="0" ixz="0" iyy="1.8538e-06" iyz="0" izz="1.5262e-06"/>
    </inertial>
    <visual>
      <geometry>
        <mesh filename="package://galbot_one_golf_description/meshes/visual/end_effectors/galbot_gripper/link3.glb" scale="1 -1 1"/>
      </geometry>
    </visual>
    <collision>
      <geometry>
        <mesh filename="package://galbot_one_golf_description/meshes/collision/end_effectors/galbot_gripper/link_3.stl" scale="1 -1 1"/>
      </geometry>
    </collision>
  </link>
  <joint name="left_gripper_joint" type="revolute">
    <parent link="left_gripper_base_link"/>
    <child link="left_gripper_r_knuckle_link"/>
    <origin rpy="1.5707963267948966 -1.2465 0" xyz="0.0745 0 0.0385"/>
    <axis xyz="0 0 -1"/>
    <limit effort="50" lower="0.0" upper="1.703" velocity="0.5"/>
  </joint>
  <joint name="left_gripper_r_inner_knuckle_joint" type="revolute">
    <parent link="left_gripper_base_link"/>
    <child link="left_gripper_r_inner_knuckle_link"/>
    <origin rpy="1.5707963267948966 -1.2465 0" xyz="0.079 0 0.026"/>
    <axis xyz="0 0 1"/>
    <limit effort="1000" lower="-3.13" upper="3.13" velocity="2.0"/>
    <mimic joint="left_gripper_joint" multiplier="-1"/>
  </joint>
  <joint name="left_gripper_r_finger_joint" type="revolute">
    <parent link="left_gripper_r_inner_knuckle_link"/>
    <child link="left_gripper_r_finger_link"/>
    <origin rpy="0 0 -1.2465" xyz="0.045 0 0"/>
    <axis xyz="0 0 1"/>
    <limit effort="1000" lower="-3.13" upper="3.13" velocity="2.0"/>
    <mimic joint="left_gripper_joint" multiplier="1"/>
  </joint>
  <joint name="left_gripper_l_knuckle_joint" type="revolute">
    <parent link="left_gripper_base_link"/>
    <child link="left_gripper_l_knuckle_link"/>
    <origin rpy="1.5707963267948966 1.2465 0" xyz="0.0745 0 -0.0385"/>
    <axis xyz="0 0 1"/>
    <limit effort="50" lower="-3.13" upper="3.13" velocity="0.5"/>
    <mimic joint="left_gripper_joint" multiplier="1"/>
  </joint>
  <joint name="left_gripper_l_inner_knuckle_joint" type="revolute">
    <parent link="left_gripper_base_link"/>
    <child link="left_gripper_l_inner_knuckle_link"/>
    <origin rpy="1.5707963267948966 1.2465 0" xyz="0.079 0 -0.026"/>
    <axis xyz="0 0 1"/>
    <limit effort="1000" lower="-3.13" upper="3.13" velocity="2.0"/>
    <mimic joint="left_gripper_joint" multiplier="1"/>
  </joint>
  <joint name="left_gripper_l_finger_joint" type="revolute">
    <parent link="left_gripper_l_inner_knuckle_link"/>
    <child link="left_gripper_l_finger_link"/>
    <origin rpy="0 0 1.2465" xyz="0.045 0 0"/>
    <axis xyz="0 0 1"/>
    <limit effort="1000" lower="-3.13" upper="3.13" velocity="2.0"/>
    <mimic joint="left_gripper_joint" multiplier="-1"/>
  </joint>
  <link name="left_gripper_tcp_link"/>
  <joint name="left_gripper_tcp_joint" type="fixed">
    <parent link="left_gripper_base_link"/>
    <child link="left_gripper_tcp_link"/>
    <origin rpy="1.5707963267948966 0 0" xyz="0.13996 0 0"/>
  </joint>
</robot>
