<mujoco model="galbot_one_golf">
  <default>
    <default class="robot">
      <default class="base_joint">
        <joint armature="0.001" damping="0.0" frictionloss="0.0" />
      </default>
      <default class="leg_joint">
        <joint stiffness="0.05" armature="0.001" damping="0.5" frictionloss="0.5" />
        <position kp="10000.0" kv="2000.0" forcerange="-845.0 845.0" />
      </default>
      <default class="head_joint">
        <joint stiffness="0.05" armature="0.001" damping="0.5" frictionloss="0.5" />
        <position kp="500.0" kv="100.0" forcerange="-4.0 4.0" />
      </default>
      <default class="arm_joint_upper">
        <joint stiffness="0.05" armature="0.001" damping="0.5" frictionloss="0.5" />
        <position kp="3000.0" kv="500.0" forcerange="-60.0 60.0" />
      </default>
      <default class="arm_joint_lower">
        <joint stiffness="0.05" armature="0.001" damping="0.5" frictionloss="0.5" />
        <position kp="1500.0" kv="300.0" forcerange="-30.0 30.0" />
      </default>
      <default class="gripper_joint">
        <joint stiffness="0.05" armature="0.001" damping="0.5" frictionloss="0.5" />
        <position kp="100.0" kv="20.0" ctrlrange="0.0 1.703" forcerange="-5.0 5.0" />
      </default>
      <default class="visual">
        <geom contype="0" conaffinity="0" group="2" />
      </default>
      <default class="collision">
        <geom contype="0" conaffinity="1" group="3" />
      </default>
    </default>
    <default class="floor">
      <geom type="plane" size="0 0 0.05" material="groundplane" />
    </default>
  </default>

  <compiler angle="radian" meshdir="." balanceinertia="true" />

  <visual>
    <global offwidth="3840" offheight="2160" />
  </visual>

  <worldbody>
    <body name="base_footprint" childclass="robot" pos="0 0 0.0051">
      <body name="base_link" pos="0 0 0.028166">
        <body name="omni_chassis_base_link">
          <inertial pos="0.02079 0.00615 0.07261" mass="30.15" diaginertia="0.3317069394 0.32081635568 0.55833152838" />
          <geom name="omni_chassis_base_link_collision" pos="0 0 0.11" type="cylinder" size="0.3 0.1" class="collision" />
          <geom type="mesh" class="visual" name="omni_chassis_base_link_visual_0" mesh="omni_chassis_base_link_chassis_0" material="chassis_glacier_white" />
          <geom type="mesh" class="visual" name="omni_chassis_base_link_visual_1" mesh="omni_chassis_base_link_chassis_1" material="chassis_plastic_black" />
          <geom type="mesh" class="visual" name="omni_chassis_base_link_visual_2" mesh="omni_chassis_base_link_chassis_2" material="chassis_plastic_gary" />
          <geom type="mesh" class="visual" name="omni_chassis_base_link_visual_3" mesh="omni_chassis_base_link_chassis_3" material="chassis_medium_yellow" />
          <geom type="mesh" class="visual" name="omni_chassis_base_link_visual_4" mesh="omni_chassis_base_link_chassis_4" material="chassis_light_silver" />
          <geom type="mesh" class="visual" name="omni_chassis_base_link_visual_5" mesh="omni_chassis_base_link_chassis_5" material="chassis_metal_aluminum" />
          <geom type="mesh" class="visual" name="omni_chassis_base_link_visual_6" mesh="omni_chassis_base_link_chassis_6" material="chassis_green_light" />
          <body name="omni_chassis_leg_mount_link" pos="0.134 0 0.1325">
            <body name="leg_base_link">
              <inertial pos="7e-05 -0.05414 0" mass="1.58" diaginertia="0.00797474 0.00248067 0.00797203" />
              <body name="leg_link1" quat="-0.1353 0.1353 0.694 0.694">
                <inertial pos="0.22308 0.00065 -0.03018" mass="17.206" diaginertia="0.07124549 1.69951784 1.67846222" />
                <joint name="leg_joint1" type="hinge" class="leg_joint" range="0.0 0.9374" axis="0 0 1" />
                <geom name="leg_link1_collision" type="mesh" mesh="leg_link1_collision_link1" class="collision" />
                <geom name="leg_link1_visual" type="mesh" mesh="leg_link1_leg1" material="leg1_metal_black" class="visual" />
                <body name="leg_link2" pos="0.45 0 0" quat="0 0.1913 0.9815 0">
                  <inertial pos="0.1798 0.00017 0.04174" mass="7.611" diaginertia="0.08014216 0.49511503 0.43725146" />
                  <joint name="leg_joint2" type="hinge" class="leg_joint" range="0.0 2.5847" axis="0 0 1" />
                  <geom name="leg_link2_collision" type="mesh" mesh="leg_link2_collision_link2" class="collision" />
                  <geom type="mesh" class="visual" name="leg_link2_visual_0" mesh="leg_link2_leg2_0" material="leg1_metal_black" />
                  <geom type="mesh" class="visual" name="leg_link2_visual_1" mesh="leg_link2_leg2_1" material="leg2_logo_white" />
                  <geom type="mesh" class="visual" name="leg_link2_visual_2" mesh="leg_link2_leg2_2" material="leg2_plastic_white" />
                  <geom type="mesh" class="visual" name="leg_link2_visual_3" mesh="leg_link2_leg2_3" material="leg2_screw_white" />
                  <body name="leg_link3" pos="0.39 0 0" quat="0 0 1 0">
                    <inertial pos="0.0001 0.00931 -0.02092" mass="4.5" diaginertia="0.01939794 0.01757571 0.01384547" />
                    <joint name="leg_joint3" type="hinge" class="leg_joint" range="0.0 2.3262" axis="0 0 1" />
                    <geom name="leg_link3_collision" type="mesh" mesh="leg_link3_collision_link3" class="collision" />
                    <geom name="leg_link3_visual" type="mesh" mesh="leg_link3_leg3" material="leg1_metal_black" class="visual" />
                    <body name="leg_link4" pos="0 0.224 0" quat="0.5 -0.5 -0.5 -0.5">
                      <inertial pos="8e-05 -0.02006 -0.04905" mass="5.05" diaginertia="0.03451013 0.03294961 0.01161759" />
                      <joint name="leg_joint4" type="hinge" class="leg_joint" range="-1.5906 1.5906" axis="0 0 1" />
                      <geom name="leg_link4_visual" type="mesh" mesh="leg_link4_leg4" material="leg1_metal_black" class="visual" />
                      <body name="leg_link5" quat="0.7071 0.7071 0 0">
                        <inertial pos="0 0.01247 0.0529" mass="1.28" diaginertia="0.0059985 0.0059157 0.00345508" />
                        <joint name="leg_joint5" type="hinge" class="leg_joint" range="-0.1645 0.1645" axis="0 0 1" />
                        <body name="leg_end_effector_mount_link">
                          <body name="torso_base_link">
                            <inertial pos="0.0053 0.1249 -0.00088" mass="6.83" diaginertia="0.12762873 0.04560482 0.13469248" />
                            <geom name="torso_base_link_collision" type="mesh" mesh="torso_base_link_collision_torso" class="collision" />
                            <geom type="mesh" class="visual" name="torso_base_link_visual_0" mesh="torso_base_link_torso_0" material="leg2_plastic_white" />
                            <geom type="mesh" class="visual" name="torso_base_link_visual_1" mesh="torso_base_link_torso_1" material="torso_Emergency_stop_tail" />
                            <geom type="mesh" class="visual" name="torso_base_link_visual_2" mesh="torso_base_link_torso_2" material="chassis_light_silver" />
                            <geom type="mesh" class="visual" name="torso_base_link_visual_3" mesh="torso_base_link_torso_3" material="torso_white_light" />
                            <geom type="mesh" class="visual" name="torso_base_link_visual_4" mesh="torso_base_link_torso_4" material="chassis_metal_aluminum" />
                            <geom type="mesh" class="visual" name="torso_base_link_visual_5" mesh="torso_base_link_torso_5" material="chassis_medium_yellow" />
                            <geom type="mesh" class="visual" name="torso_base_link_visual_6" mesh="torso_base_link_torso_6" material="torso_camera" />
                            <geom type="mesh" class="visual" name="torso_base_link_visual_7" mesh="torso_base_link_torso_7" material="chassis_plastic_black" />
                            <geom type="mesh" class="visual" name="torso_base_link_visual_8" mesh="torso_base_link_torso_8" material="chassis_plastic_gary" />
                            <geom type="mesh" class="visual" name="torso_base_link_visual_9" mesh="torso_base_link_torso_9" material="torso_emergency_stop_switch" />
                            <body name="torso_head_mount_link" pos="0 0.37711 0" quat="0.5 -0.5 -0.5 -0.5">
                              <body name="head_base_link">
                                <inertial pos="-0.00019 0.00012 -0.0832" mass="0.39" diaginertia="0.00352162 0.00343251 0.00044115" />
                                <body name="head_link1">
                                  <inertial pos="1e-05 0.00189 -0.04337" mass="1.5695" diaginertia="0.0069002956 0.0068330036 0.0011696764" />
                                  <joint name="head_joint1" type="hinge" class="head_joint" range="-1.5208 1.5208" axis="0 0 1" />
                                  <geom name="head_link1_collision" type="mesh" mesh="head_link1_collision_head_link1" class="collision" />
                                  <geom name="head_link1_visual" type="mesh" mesh="head_link1_head_link1" material="chassis_plastic_black" class="visual" />
                                  <body name="head_link2" quat="0.7071 -0.7071 0 0">
                                    <inertial pos="0.03563 -0.03998 0.00678" mass="0.81" diaginertia="0.00399161 0.00372602 0.00553062" />
                                    <joint name="head_joint2" type="hinge" class="head_joint" range="-0.2143461 0.4935988" axis="0 0 1" />
                                    <geom name="head_link2_collision" type="mesh" mesh="head_link2_collision_head_link2" class="collision" />
                                    <geom type="mesh" class="visual" name="head_link2_visual_0" mesh="head_link2_head_link2_0" material="torso_white_light" />
                                    <geom type="mesh" class="visual" name="head_link2_visual_1" mesh="head_link2_head_link2_1" material="chassis_plastic_black" />
                                    <geom type="mesh" class="visual" name="head_link2_visual_2" mesh="head_link2_head_link2_2" material="torso_camera" />
                                    <geom type="mesh" class="visual" name="head_link2_visual_3" mesh="head_link2_head_link2_3" material="leg2_plastic_white" />
                                    <geom type="mesh" class="visual" name="head_link2_visual_4" mesh="head_link2_head_link2_4" material="head_link2_glacier_428c" />
                                    <body name="head_end_effector_mount_link" />
                                  </body>
                                </body>
                              </body>
                            </body>
                            <body name="torso_left_arm_mount_link" pos="0.20843 0.172 0" quat="0.7071 0 0.7071 0">
                              <body name="left_arm_base_link">
                                <inertial pos="0.0 0.0 -0.10506" mass="0.92" diaginertia="0.01075595 0.01077842 0.0007042000000000001" />
                                <body name="left_arm_link1" quat="0.9659 0 0 0.2588">
                                  <inertial pos="0.0 0.0009699999999999999 -0.015390000000000001" mass="1.6" diaginertia="0.00332981 0.00339121 0.0016524" />
                                  <joint name="left_arm_joint1" type="hinge" class="arm_joint_upper" range="-3.00432619 3.00432619" axis="0 0 1" />
                                  <geom name="left_arm_link1_collision" type="mesh" mesh="left_arm_link1_collision_link1" class="collision" />
                                  <geom name="left_arm_link1_visual" type="mesh" mesh="left_arm_link1_link1" material="leg1_metal_black" class="visual" />
                                  <body name="left_arm_link2" quat="0 0 0.7071 0.7071">
                                    <inertial pos="0.0 0.09558 0.010150000000000001" mass="1.43" diaginertia="0.01937881 0.0015791400000000001 0.018951810000000003" />
                                    <joint name="left_arm_joint2" type="hinge" class="arm_joint_upper" range="-1.608062789 1.608062789" axis="0 0 1" />
                                    <geom name="left_arm_link2_collision" type="mesh" mesh="left_arm_link2_collision_link2" class="collision" />
                                    <geom type="mesh" class="visual" name="left_arm_link2_visual_0" mesh="left_arm_link2_link2_0" material="chassis_plastic_black" />
                                    <geom type="mesh" class="visual" name="left_arm_link2_visual_1" mesh="left_arm_link2_link2_1" material="leg2_plastic_white" />
                                    <body name="left_arm_link3" pos="0 0.35 0" quat="-0.3536 0.3536 -0.6124 -0.6124">
                                      <inertial pos="0.0 0.00088 -0.04936" mass="1.43" diaginertia="0.01187457 0.01178759 0.0013715" />
                                      <joint name="left_arm_joint3" type="hinge" class="arm_joint_lower" range="-2.916972222 2.916972222" axis="0 0 1" />
                                      <geom name="left_arm_link3_collision" type="mesh" mesh="left_arm_link3_collision_link3" class="collision" />
                                      <geom type="mesh" class="visual" name="left_arm_link3_visual_0" mesh="left_arm_link3_link3_0" material="chassis_light_silver" />
                                      <geom type="mesh" class="visual" name="left_arm_link3_visual_2" mesh="left_arm_link3_link3_1" material="link3_metal_aluminum" />
                                      <body name="left_arm_link4" quat="0 0 0.7071 0.7071">
                                        <inertial pos="0.0 0.05614 0.019170000000000003" mass="1.1" diaginertia="0.00701388 0.00161854 0.0065011999999999995" />
                                        <joint name="left_arm_joint4" type="hinge" class="arm_joint_lower" range="-2.5679938779914946 1.869862177" axis="0 0 1" />
                                        <geom name="left_arm_link4_collision" type="mesh" mesh="left_arm_link4_collision_link4" class="collision" />
                                        <geom type="mesh" class="visual" name="left_arm_link4_visual_0" mesh="left_arm_link4_link4_0" material="link3_metal_aluminum" />
                                        <geom type="mesh" class="visual" name="left_arm_link4_visual_2" mesh="left_arm_link4_link4_1" material="leg2_plastic_white" />
                                        <body name="left_arm_link5" pos="0 0.36 0" quat="0.7071 -0.7071 0 0">
                                          <inertial pos="0.00044 0.0016899999999999999 -0.13306" mass="1.15" diaginertia="0.025809930000000002 0.02530313 0.00115848" />
                                          <joint name="left_arm_joint5" type="hinge" class="arm_joint_lower" range="-2.916972222 2.916972222" axis="0 0 1" />
                                          <geom name="left_arm_link5_collision" type="mesh" mesh="left_arm_link5_collision_link5" class="collision" />
                                          <geom type="mesh" class="visual" name="left_arm_link5_visual_0" mesh="left_arm_link5_link5_0" material="chassis_light_silver" />
                                          <geom type="mesh" class="visual" name="left_arm_link5_visual_1" mesh="left_arm_link5_link5_1" material="leg2_plastic_white" />
                                          <body name="left_arm_link6" quat="0.5 0.5 0.5 -0.5">
                                            <inertial pos="-0.00088 -0.0072699999999999996 -0.00011999999999999999" mass="0.47" diaginertia="0.00027557 0.00028977999999999995 0.00029684" />
                                            <joint name="left_arm_joint6" type="hinge" class="arm_joint_lower" range="-0.8226646259971648 0.7353981633974483" axis="0 0 1" />
                                            <geom name="left_arm_link6_collision" type="mesh" mesh="left_arm_link6_collision_link6" class="collision" />
                                            <geom type="mesh" class="visual" name="left_arm_link6_visual_0" mesh="left_arm_link6_link6_0" material="chassis_light_silver" />
                                            <geom type="mesh" class="visual" name="left_arm_link6_visual_2" mesh="left_arm_link6_link6_1" material="leg2_plastic_white" />
                                            <body name="left_arm_link7" quat="0.7071 0.7071 0 0">
                                              <inertial pos="-0.05751 -0.00684 0.011869999999999999" mass="0.8" diaginertia="0.00117613 0.00423935 0.00417642" />
                                              <joint name="left_arm_joint7" type="hinge" class="arm_joint_lower" range="-1.538202778 1.538202778" axis="0 0 1" />
                                              <geom name="left_arm_link7_collision" type="mesh" mesh="left_arm_link7_collision_link7" class="collision" />
                                              <geom type="mesh" class="visual" name="left_arm_link7_visual_0" mesh="left_arm_link7_link7_0" material="chassis_light_silver" />
                                              <geom type="mesh" class="visual" name="left_arm_link7_visual_2" mesh="left_arm_link7_link7_1" material="leg2_plastic_white" />
                                              <geom type="mesh" class="visual" name="left_arm_link7_visual_4" mesh="left_arm_link7_link7_2" material="link3_metal_aluminum" />
                                              <body name="left_arm_end_effector_mount_link" pos="-0.10926 0 0" quat="0 0 1 0">
                                                <inertial pos="0 0 0" mass="1e-06" diaginertia="1e-09 1e-09 1e-09" />
                                                <body name="left_gripper_flange_link" quat="0.7071 0.7071 0 0">
                                                  <inertial pos="0.0030662 -1.4019E-18 3.383E-18" mass="0.031005" diaginertia="2.2585e-05 1.141e-05 1.141e-05" />
                                                  <geom name="left_gripper_flange_link_visual" type="mesh" mesh="left_gripper_flange_link_flange" material="leg1_metal_black" class="visual" />
                                                  <body name="left_gripper_base_link" pos="0.0065 0 0">
                                                    <inertial pos="0.037051 -6.4001E-05 6.4706E-05" mass="0.061747" diaginertia="2.5813e-05 7.2859e-05 5.7173e-05" />
                                                    <geom name="left_gripper_base_link_collision" type="mesh" mesh="left_gripper_base_link_collision_base_link" class="collision" />
                                                    <geom type="mesh" class="visual" name="left_gripper_base_link_visual_0" mesh="left_gripper_base_link_base_link_0" material="leg1_metal_black" />
                                                    <geom type="mesh" class="visual" name="left_gripper_base_link_visual_1" mesh="left_gripper_base_link_base_link_1" material="chassis_plastic_black" />
                                                    <body name="left_gripper_r_knuckle_link" pos="0.0745 0 0.0385" quat="0.5742 0.5742 -0.4127 0.4127">
                                                      <inertial pos="0.024101 0 0" mass="0.0070682" diaginertia="9.2131e-08 1.559e-06 1.4931e-06" />
                                                      <joint name="left_gripper_joint" type="hinge" class="gripper_joint" range="0.0 1.703" axis="0 0 -1" />
                                                      <geom name="left_gripper_r_knuckle_link_collision" type="mesh" mesh="left_gripper_r_knuckle_link_collision_link_1" class="collision" />
                                                      <geom type="mesh" class="visual" name="left_gripper_r_knuckle_link_visual_0" mesh="left_gripper_r_knuckle_link_link1_0" material="chassis_metal_aluminum" />
                                                      <geom type="mesh" class="visual" name="left_gripper_r_knuckle_link_visual_1" mesh="left_gripper_r_knuckle_link_link1_1" material="chassis_light_silver" />
                                                    </body>
                                                    <body name="left_gripper_r_inner_knuckle_link" pos="0.079 0 0.026" quat="0.5742 0.5742 -0.4127 0.4127">
                                                      <inertial pos="0.023769 0 0" mass="0.007802" diaginertia="1.044e-07 1.6385e-06 1.566e-06" />
                                                      <joint name="left_gripper_r_inner_knuckle_joint" type="hinge" range="-3.13 3.13" axis="0 0 1" />
                                                      <geom name="left_gripper_r_inner_knuckle_link_collision" type="mesh" mesh="left_gripper_r_inner_knuckle_link_collision_link_2" class="collision" />
                                                      <geom type="mesh" class="visual" name="left_gripper_r_inner_knuckle_link_visual_0" mesh="left_gripper_r_inner_knuckle_link_link2_0" material="chassis_metal_aluminum" />
                                                      <geom type="mesh" class="visual" name="left_gripper_r_inner_knuckle_link_visual_1" mesh="left_gripper_r_inner_knuckle_link_link2_1" material="chassis_light_silver" />
                                                      <body name="left_gripper_r_finger_link" pos="0.045 0 0" quat="0.812 0 0 -0.5837">
                                                        <inertial pos="0.016809 -0.0019094 0" mass="0.015957" diaginertia="5.5426e-07 1.8538e-06 1.5262e-06" />
                                                        <joint name="left_gripper_r_finger_joint" type="hinge" range="-3.13 3.13" axis="0 0 1" />
                                                        <geom name="left_gripper_r_finger_link_collision" type="mesh" mesh="left_gripper_r_finger_link_collision_link_3_1" class="collision" />
                                                        <geom type="mesh" class="visual" name="left_gripper_r_finger_link_visual_0" mesh="left_gripper_r_finger_link_link3_0_1" material="chassis_plastic_black" />
                                                        <geom type="mesh" class="visual" name="left_gripper_r_finger_link_visual_2" mesh="left_gripper_r_finger_link_link3_1_1" material="chassis_light_silver" />
                                                        <geom type="mesh" class="visual" name="left_gripper_r_finger_link_visual_4" mesh="left_gripper_r_finger_link_link3_2_1" material="chassis_metal_aluminum" />
                                                      </body>
                                                    </body>
                                                    <body name="left_gripper_l_knuckle_link" pos="0.0745 0 -0.0385" quat="0.5742 0.5742 0.4127 -0.4127">
                                                      <inertial pos="0.024101 0 0" mass="0.0070682" diaginertia="9.2131e-08 1.559e-06 1.4931e-06" />
                                                      <joint name="left_gripper_l_knuckle_joint" type="hinge" range="-3.13 3.13" axis="0 0 1" />
                                                      <geom name="left_gripper_l_knuckle_link_collision" type="mesh" mesh="left_gripper_r_knuckle_link_collision_link_1" class="collision" />
                                                      <geom type="mesh" class="visual" name="left_gripper_l_knuckle_link_visual_0" mesh="left_gripper_r_knuckle_link_link1_0" material="chassis_metal_aluminum" />
                                                      <geom type="mesh" class="visual" name="left_gripper_l_knuckle_link_visual_1" mesh="left_gripper_r_knuckle_link_link1_1" material="chassis_light_silver" />
                                                    </body>
                                                    <body name="left_gripper_l_inner_knuckle_link" pos="0.079 0 -0.026" quat="0.5742 0.5742 0.4127 -0.4127">
                                                      <inertial pos="0.023769 0 0" mass="0.007802" diaginertia="1.044e-07 1.6385e-06 1.566e-06" />
                                                      <joint name="left_gripper_l_inner_knuckle_joint" type="hinge" range="-3.13 3.13" axis="0 0 1" />
                                                      <geom name="left_gripper_l_inner_knuckle_link_collision" type="mesh" mesh="left_gripper_r_inner_knuckle_link_collision_link_2" class="collision" />
                                                      <geom type="mesh" class="visual" name="left_gripper_l_inner_knuckle_link_visual_0" mesh="left_gripper_r_inner_knuckle_link_link2_0" material="chassis_metal_aluminum" />
                                                      <geom type="mesh" class="visual" name="left_gripper_l_inner_knuckle_link_visual_1" mesh="left_gripper_r_inner_knuckle_link_link2_1" material="chassis_light_silver" />
                                                      <body name="left_gripper_l_finger_link" pos="0.045 0 0" quat="0.812 0 0 0.5837">
                                                        <inertial pos="0.016809 0.0019094 0" mass="0.015957" diaginertia="5.5426e-07 1.8538e-06 1.5262e-06" />
                                                        <joint name="left_gripper_l_finger_joint" type="hinge" range="-3.13 3.13" axis="0 0 1" />
                                                        <geom name="left_gripper_l_finger_link_collision" type="mesh" mesh="left_gripper_l_finger_link_collision_link_3" class="collision" />
                                                        <geom type="mesh" class="visual" name="left_gripper_l_finger_link_visual_0" mesh="left_gripper_l_finger_link_link3_0" material="chassis_plastic_black" />
                                                        <geom type="mesh" class="visual" name="left_gripper_l_finger_link_visual_2" mesh="left_gripper_l_finger_link_link3_1" material="chassis_light_silver" />
                                                        <geom type="mesh" class="visual" name="left_gripper_l_finger_link_visual_4" mesh="left_gripper_l_finger_link_link3_2" material="chassis_metal_aluminum" />
                                                      </body>
                                                    </body>
                                                    <body name="left_gripper_tcp_link" pos="0.13996 0 0" quat="0.7071 0.7071 0 0" />
                                                  </body>
                                                </body>
                                              </body>
                                              <body name="left_arm_wrist_camera_stand">
                                                <inertial pos="-0.0621229724155358 -0.0628379837355285 -0.00140310958315455" mass="0.0492751941348016" diaginertia="3.66069470547417e-05 3.08593710158624e-05 8.80145863410975e-06" />
                                                <geom name="left_arm_wrist_camera_stand_collision" type="mesh" mesh="left_arm_wrist_camera_stand_collision_d405" class="collision" />
                                                <geom name="left_arm_wrist_camera_stand_visual" type="mesh" mesh="left_arm_wrist_camera_stand_d405_stand" material="link3_metal_aluminum" class="visual" />
                                                <body name="left_wrist_camera_link" pos="-0.0822 0 -0.06842" quat="0 -0.6746 0 0.7382">
                                                  <geom type="mesh" class="visual" name="left_wrist_camera_link_visual_0" mesh="left_wrist_camera_link_d405_0" material="torso_camera" />
                                                  <geom type="mesh" class="visual" name="left_wrist_camera_link_visual_1" mesh="left_wrist_camera_link_d405_1" material="d405_silver" />
                                                  <geom type="mesh" class="visual" name="left_wrist_camera_link_visual_2" mesh="left_wrist_camera_link_d405_2" material="d405_black" />
                                                </body>
                                              </body>
                                            </body>
                                          </body>
                                        </body>
                                      </body>
                                    </body>
                                  </body>
                                </body>
                              </body>
                            </body>
                            <body name="torso_right_arm_mount_link" pos="-0.20843 0.172 0" quat="0 0.7071 0 -0.7071">
                              <body name="right_arm_base_link">
                                <inertial pos="0.0 0.0 -0.10506" mass="0.92" diaginertia="0.01075595 0.01077842 0.0007042000000000001" />
                                <body name="right_arm_link1" quat="0.9659 0 0 -0.2588">
                                  <inertial pos="0.0 -0.0009699999999999999 -0.015390000000000001" mass="1.6" diaginertia="0.00332981 0.00339121 0.0016524" />
                                  <joint name="right_arm_joint1" type="hinge" class="arm_joint_upper" range="-3.00432619 3.00432619" axis="0 0 1" />
                                  <geom name="right_arm_link1_collision" type="mesh" mesh="right_arm_link1_collision_link1_1" class="collision" />
                                  <geom name="right_arm_link1_visual" type="mesh" mesh="right_arm_link1_link1_1" material="leg1_metal_black" class="visual" />
                                  <body name="right_arm_link2" quat="0 0 -0.7071 0.7071">
                                    <inertial pos="0.0 -0.09558 0.010150000000000001" mass="1.43" diaginertia="0.01937881 0.0015791400000000001 0.018951810000000003" />
                                    <joint name="right_arm_joint2" type="hinge" class="arm_joint_upper" range="-1.608062789 1.608062789" axis="0 0 1" />
                                    <geom name="right_arm_link2_collision" type="mesh" mesh="right_arm_link2_collision_link2_1" class="collision" />
                                    <geom name="right_arm_link2_visual" type="mesh" mesh="right_arm_link2_link2_right" material="leg2_plastic_white" class="visual" />
                                    <body name="right_arm_link3" pos="0 -0.35 0" quat="0.3536 0.3536 0.6124 -0.6124">
                                      <inertial pos="0.0 -0.00088 -0.04936" mass="1.43" diaginertia="0.01187457 0.01178759 0.0013715" />
                                      <joint name="right_arm_joint3" type="hinge" class="arm_joint_lower" range="-2.916972222 2.916972222" axis="0 0 1" />
                                      <geom name="right_arm_link3_collision" type="mesh" mesh="right_arm_link3_collision_link3_1" class="collision" />
                                      <geom type="mesh" class="visual" name="right_arm_link3_visual_0" mesh="right_arm_link3_link3_0_1" material="chassis_light_silver" />
                                      <geom type="mesh" class="visual" name="right_arm_link3_visual_2" mesh="right_arm_link3_link3_1_1" material="link3_metal_aluminum" />
                                      <body name="right_arm_link4" quat="0 0 -0.7071 0.7071">
                                        <inertial pos="0.0 -0.05614 0.019170000000000003" mass="1.1" diaginertia="0.00701388 0.00161854 0.0065011999999999995" />
                                        <joint name="right_arm_joint4" type="hinge" class="arm_joint_lower" range="-1.869862177 2.5679938779914946" axis="0 0 1" />
                                        <geom name="right_arm_link4_collision" type="mesh" mesh="right_arm_link4_collision_link4_1" class="collision" />
                                        <geom type="mesh" class="visual" name="right_arm_link4_visual_0" mesh="right_arm_link4_link4_0_1" material="link3_metal_aluminum" />
                                        <geom type="mesh" class="visual" name="right_arm_link4_visual_2" mesh="right_arm_link4_link4_1_1" material="leg2_plastic_white" />
                                        <body name="right_arm_link5" pos="0 -0.36 0" quat="0 0 -0.7071 0.7071">
                                          <inertial pos="0.00044 0.0016899999999999999 -0.13306" mass="1.15" diaginertia="0.025809930000000002 0.02530313 0.00115848" />
                                          <joint name="right_arm_joint5" type="hinge" class="arm_joint_lower" range="-2.916972222 2.916972222" axis="0 0 1" />
                                          <geom name="right_arm_link5_collision" type="mesh" mesh="left_arm_link5_collision_link5" class="collision" />
                                          <geom type="mesh" class="visual" name="right_arm_link5_visual_0" mesh="left_arm_link5_link5_0" material="chassis_light_silver" />
                                          <geom type="mesh" class="visual" name="right_arm_link5_visual_1" mesh="left_arm_link5_link5_1" material="leg2_plastic_white" />
                                          <body name="right_arm_link6" quat="0.5 0.5 0.5 -0.5">
                                            <inertial pos="-0.00088 0.0072699999999999996 -0.00011999999999999999" mass="0.47" diaginertia="0.00027557 0.00028977999999999995 0.00029684" />
                                            <joint name="right_arm_joint6" type="hinge" class="arm_joint_lower" range="-0.7353981633974483 0.8226646259971648" axis="0 0 1" />
                                            <geom name="right_arm_link6_collision" type="mesh" mesh="right_arm_link6_collision_link6_1" class="collision" />
                                            <geom type="mesh" class="visual" name="right_arm_link6_visual_0" mesh="right_arm_link6_link6_0_1" material="chassis_light_silver" />
                                            <geom type="mesh" class="visual" name="right_arm_link6_visual_2" mesh="right_arm_link6_link6_1_1" material="leg2_plastic_white" />
                                            <body name="right_arm_link7" quat="0.7071 -0.7071 0 0">
                                              <inertial pos="-0.05751 0.00684 0.011869999999999999" mass="0.8" diaginertia="0.00117613 0.00423935 0.00417642" />
                                              <joint name="right_arm_joint7" type="hinge" class="arm_joint_lower" range="-1.538202778 1.538202778" axis="0 0 1" />
                                              <geom name="right_arm_link7_collision" type="mesh" mesh="right_arm_link7_collision_link7_1" class="collision" />
                                              <geom type="mesh" class="visual" name="right_arm_link7_visual_0" mesh="right_arm_link7_link7_0_1" material="chassis_light_silver" />
                                              <geom type="mesh" class="visual" name="right_arm_link7_visual_2" mesh="right_arm_link7_link7_1_1" material="leg2_plastic_white" />
                                              <geom type="mesh" class="visual" name="right_arm_link7_visual_4" mesh="right_arm_link7_link7_2_1" material="link3_metal_aluminum" />
                                              <body name="right_arm_end_effector_mount_link" pos="-0.10926 0 0" quat="0 0 1 0">
                                                <inertial pos="0 0 0" mass="1e-06" diaginertia="1e-09 1e-09 1e-09" />
                                                <body name="right_gripper_flange_link" quat="0.7071 0.7071 0 0">
                                                  <inertial pos="0.0030662 -1.4019E-18 3.383E-18" mass="0.031005" diaginertia="2.2585e-05 1.141e-05 1.141e-05" />
                                                  <geom name="right_gripper_flange_link_visual" type="mesh" mesh="left_gripper_flange_link_flange" material="leg1_metal_black" class="visual" />
                                                  <body name="right_gripper_base_link" pos="0.0065 0 0">
                                                    <inertial pos="0.037051 -6.4001E-05 6.4706E-05" mass="0.061747" diaginertia="2.5813e-05 7.2859e-05 5.7173e-05" />
                                                    <geom name="right_gripper_base_link_collision" type="mesh" mesh="left_gripper_base_link_collision_base_link" class="collision" />
                                                    <geom type="mesh" class="visual" name="right_gripper_base_link_visual_0" mesh="left_gripper_base_link_base_link_0" material="leg1_metal_black" />
                                                    <geom type="mesh" class="visual" name="right_gripper_base_link_visual_1" mesh="left_gripper_base_link_base_link_1" material="chassis_plastic_black" />
                                                    <body name="right_gripper_r_knuckle_link" pos="0.0745 0 0.0385" quat="0.5742 0.5742 -0.4127 0.4127">
                                                      <inertial pos="0.024101 0 0" mass="0.0070682" diaginertia="9.2131e-08 1.559e-06 1.4931e-06" />
                                                      <joint name="right_gripper_joint" type="hinge" class="gripper_joint" range="0.0 1.703" axis="0 0 -1" />
                                                      <geom name="right_gripper_r_knuckle_link_collision" type="mesh" mesh="left_gripper_r_knuckle_link_collision_link_1" class="collision" />
                                                      <geom type="mesh" class="visual" name="right_gripper_r_knuckle_link_visual_0" mesh="left_gripper_r_knuckle_link_link1_0" material="chassis_metal_aluminum" />
                                                      <geom type="mesh" class="visual" name="right_gripper_r_knuckle_link_visual_1" mesh="left_gripper_r_knuckle_link_link1_1" material="chassis_light_silver" />
                                                    </body>
                                                    <body name="right_gripper_r_inner_knuckle_link" pos="0.079 0 0.026" quat="0.5742 0.5742 -0.4127 0.4127">
                                                      <inertial pos="0.023769 0 0" mass="0.007802" diaginertia="1.044e-07 1.6385e-06 1.566e-06" />
                                                      <joint name="right_gripper_r_inner_knuckle_joint" type="hinge" range="-3.13 3.13" axis="0 0 1" />
                                                      <geom name="right_gripper_r_inner_knuckle_link_collision" type="mesh" mesh="left_gripper_r_inner_knuckle_link_collision_link_2" class="collision" />
                                                      <geom type="mesh" class="visual" name="right_gripper_r_inner_knuckle_link_visual_0" mesh="left_gripper_r_inner_knuckle_link_link2_0" material="chassis_metal_aluminum" />
                                                      <geom type="mesh" class="visual" name="right_gripper_r_inner_knuckle_link_visual_1" mesh="left_gripper_r_inner_knuckle_link_link2_1" material="chassis_light_silver" />
                                                      <body name="right_gripper_r_finger_link" pos="0.045 0 0" quat="0.812 0 0 -0.5837">
                                                        <inertial pos="0.016809 -0.0019094 0" mass="0.015957" diaginertia="5.5426e-07 1.8538e-06 1.5262e-06" />
                                                        <joint name="right_gripper_r_finger_joint" type="hinge" range="-3.13 3.13" axis="0 0 1" />
                                                        <geom name="right_gripper_r_finger_link_collision" type="mesh" mesh="left_gripper_r_finger_link_collision_link_3_1" class="collision" />
                                                        <geom type="mesh" class="visual" name="right_gripper_r_finger_link_visual_0" mesh="left_gripper_r_finger_link_link3_0_1" material="chassis_plastic_black" />
                                                        <geom type="mesh" class="visual" name="right_gripper_r_finger_link_visual_2" mesh="left_gripper_r_finger_link_link3_1_1" material="chassis_light_silver" />
                                                        <geom type="mesh" class="visual" name="right_gripper_r_finger_link_visual_4" mesh="left_gripper_r_finger_link_link3_2_1" material="chassis_metal_aluminum" />
                                                      </body>
                                                    </body>
                                                    <body name="right_gripper_l_knuckle_link" pos="0.0745 0 -0.0385" quat="0.5742 0.5742 0.4127 -0.4127">
                                                      <inertial pos="0.024101 0 0" mass="0.0070682" diaginertia="9.2131e-08 1.559e-06 1.4931e-06" />
                                                      <joint name="right_gripper_l_knuckle_joint" type="hinge" range="-3.13 3.13" axis="0 0 1" />
                                                      <geom name="right_gripper_l_knuckle_link_collision" type="mesh" mesh="left_gripper_r_knuckle_link_collision_link_1" class="collision" />
                                                      <geom type="mesh" class="visual" name="right_gripper_l_knuckle_link_visual_0" mesh="left_gripper_r_knuckle_link_link1_0" material="chassis_metal_aluminum" />
                                                      <geom type="mesh" class="visual" name="right_gripper_l_knuckle_link_visual_1" mesh="left_gripper_r_knuckle_link_link1_1" material="chassis_light_silver" />
                                                    </body>
                                                    <body name="right_gripper_l_inner_knuckle_link" pos="0.079 0 -0.026" quat="0.5742 0.5742 0.4127 -0.4127">
                                                      <inertial pos="0.023769 0 0" mass="0.007802" diaginertia="1.044e-07 1.6385e-06 1.566e-06" />
                                                      <joint name="right_gripper_l_inner_knuckle_joint" type="hinge" range="-3.13 3.13" axis="0 0 1" />
                                                      <geom name="right_gripper_l_inner_knuckle_link_collision" type="mesh" mesh="left_gripper_r_inner_knuckle_link_collision_link_2" class="collision" />
                                                      <geom type="mesh" class="visual" name="right_gripper_l_inner_knuckle_link_visual_0" mesh="left_gripper_r_inner_knuckle_link_link2_0" material="chassis_metal_aluminum" />
                                                      <geom type="mesh" class="visual" name="right_gripper_l_inner_knuckle_link_visual_1" mesh="left_gripper_r_inner_knuckle_link_link2_1" material="chassis_light_silver" />
                                                      <body name="right_gripper_l_finger_link" pos="0.045 0 0" quat="0.812 0 0 0.5837">
                                                        <inertial pos="0.016809 0.0019094 0" mass="0.015957" diaginertia="5.5426e-07 1.8538e-06 1.5262e-06" />
                                                        <joint name="right_gripper_l_finger_joint" type="hinge" range="-3.13 3.13" axis="0 0 1" />
                                                        <geom name="right_gripper_l_finger_link_collision" type="mesh" mesh="left_gripper_l_finger_link_collision_link_3" class="collision" />
                                                        <geom type="mesh" class="visual" name="right_gripper_l_finger_link_visual_0" mesh="left_gripper_l_finger_link_link3_0" material="chassis_plastic_black" />
                                                        <geom type="mesh" class="visual" name="right_gripper_l_finger_link_visual_2" mesh="left_gripper_l_finger_link_link3_1" material="chassis_light_silver" />
                                                        <geom type="mesh" class="visual" name="right_gripper_l_finger_link_visual_4" mesh="left_gripper_l_finger_link_link3_2" material="chassis_metal_aluminum" />
                                                      </body>
                                                    </body>
                                                    <body name="right_gripper_tcp_link" pos="0.13996 0 0" quat="0.7071 0.7071 0 0" />
                                                  </body>
                                                </body>
                                              </body>
                                              <body name="right_arm_wrist_camera_stand">
                                                <inertial pos="-0.0621229724155358 -0.0628379837355285 -0.00140310958315455" mass="0.0492751941348016" diaginertia="3.66069470547417e-05 3.08593710158624e-05 8.80145863410975e-06" />
                                                <geom name="right_arm_wrist_camera_stand_collision" type="mesh" mesh="left_arm_wrist_camera_stand_collision_d405" class="collision" />
                                                <geom name="right_arm_wrist_camera_stand_visual" type="mesh" mesh="left_arm_wrist_camera_stand_d405_stand" material="link3_metal_aluminum" class="visual" />
                                                <body name="right_wrist_camera_link" pos="-0.0822 0 -0.06842" quat="0 -0.6746 0 0.7382">
                                                  <geom type="mesh" class="visual" name="right_wrist_camera_link_visual_0" mesh="left_wrist_camera_link_d405_0" material="torso_camera" />
                                                  <geom type="mesh" class="visual" name="right_wrist_camera_link_visual_1" mesh="left_wrist_camera_link_d405_1" material="d405_silver" />
                                                  <geom type="mesh" class="visual" name="right_wrist_camera_link_visual_2" mesh="left_wrist_camera_link_d405_2" material="d405_black" />
                                                </body>
                                              </body>
                                            </body>
                                          </body>
                                        </body>
                                      </body>
                                    </body>
                                  </body>
                                </body>
                              </body>
                            </body>
                          </body>
                        </body>
                      </body>
                    </body>
                  </body>
                </body>
              </body>
            </body>
          </body>
          <body name="wheel_1" pos="0.176493 0.176493 0.071834" quat="0.3827 0 0 -0.9239">
            <inertial pos="0.0026089441594678298 -1.3189703553351252e-07 2.8695680726054107e-07" mass="4.24803000494366" diaginertia="0.012235 0.006629 0.006629" />
            <geom name="wheel_1_collision_0" pos="0 0.025 0.0" type="sphere" size="0.08" class="collision" />
            <geom name="wheel_1_collision_1" pos="0 0.02022542485937369 0.014694631307311828" type="sphere" size="0.08" class="collision" />
            <geom name="wheel_1_collision_2" pos="0 0.007725424859373687 0.02377641290737884" type="sphere" size="0.08" class="collision" />
            <geom name="wheel_1_collision_3" pos="0 -0.007725424859373684 0.023776412907378842" type="sphere" size="0.08" class="collision" />
            <geom name="wheel_1_collision_4" pos="0 -0.020225424859373686 0.014694631307311832" type="sphere" size="0.08" class="collision" />
            <geom name="wheel_1_collision_5" pos="0 -0.025 3.061616997868383e-18" type="sphere" size="0.08" class="collision" />
            <geom name="wheel_1_collision_6" pos="0 -0.02022542485937369 -0.014694631307311827" type="sphere" size="0.08" class="collision" />
            <geom name="wheel_1_collision_7" pos="0 -0.007725424859373689 -0.02377641290737884" type="sphere" size="0.08" class="collision" />
            <geom name="wheel_1_collision_8" pos="0 0.007725424859373681 -0.023776412907378842" type="sphere" size="0.08" class="collision" />
            <geom name="wheel_1_collision_9" pos="0 0.020225424859373686 -0.014694631307311835" type="sphere" size="0.08" class="collision" />
            <geom type="mesh" class="visual" name="wheel_1_visual_0" mesh="wheel_1_omniwheel_10_0" material="d405_black" />
            <geom type="mesh" class="visual" name="wheel_1_visual_1" mesh="wheel_1_omniwheel_10_1" material="leg2_logo_white" />
            <geom type="mesh" class="visual" name="wheel_1_visual_2" mesh="wheel_1_merged_wheel" material="omniwheel_10_wheel" pos="0 0 0" />
          </body>
          <body name="wheel_2" pos="-0.176493 0.176493 0.071834" quat="0.9239 0 0 -0.3827">
            <inertial pos="0.0026089441594678298 -1.3189703553351252e-07 2.8695680726054107e-07" mass="4.24803000494366" diaginertia="0.012235 0.006629 0.006629" />
            <geom name="wheel_2_collision_0" pos="0 0.025 0.0" type="sphere" size="0.08" class="collision" />
            <geom name="wheel_2_collision_1" pos="0 0.02022542485937369 0.014694631307311828" type="sphere" size="0.08" class="collision" />
            <geom name="wheel_2_collision_2" pos="0 0.007725424859373687 0.02377641290737884" type="sphere" size="0.08" class="collision" />
            <geom name="wheel_2_collision_3" pos="0 -0.007725424859373684 0.023776412907378842" type="sphere" size="0.08" class="collision" />
            <geom name="wheel_2_collision_4" pos="0 -0.020225424859373686 0.014694631307311832" type="sphere" size="0.08" class="collision" />
            <geom name="wheel_2_collision_5" pos="0 -0.025 3.061616997868383e-18" type="sphere" size="0.08" class="collision" />
            <geom name="wheel_2_collision_6" pos="0 -0.02022542485937369 -0.014694631307311827" type="sphere" size="0.08" class="collision" />
            <geom name="wheel_2_collision_7" pos="0 -0.007725424859373689 -0.02377641290737884" type="sphere" size="0.08" class="collision" />
            <geom name="wheel_2_collision_8" pos="0 0.007725424859373681 -0.023776412907378842" type="sphere" size="0.08" class="collision" />
            <geom name="wheel_2_collision_9" pos="0 0.020225424859373686 -0.014694631307311835" type="sphere" size="0.08" class="collision" />
            <geom type="mesh" class="visual" name="wheel_2_visual_0" mesh="wheel_1_omniwheel_10_0" material="d405_black" />
            <geom type="mesh" class="visual" name="wheel_2_visual_1" mesh="wheel_1_omniwheel_10_1" material="leg2_logo_white" />
            <geom type="mesh" class="visual" name="wheel_2_visual_2" mesh="wheel_2_merged_wheel" material="omniwheel_10_wheel" pos="0 0 0" />
          </body>
          <body name="wheel_3" pos="-0.176493 -0.176493 0.071834" quat="0.9239 0 0 0.3827">
            <inertial pos="0.0026089441594678298 -1.3189703553351252e-07 2.8695680726054107e-07" mass="4.24803000494366" diaginertia="0.012235 0.006629 0.006629" />
            <geom name="wheel_3_collision_0" pos="0 0.025 0.0" type="sphere" size="0.08" class="collision" />
            <geom name="wheel_3_collision_1" pos="0 0.02022542485937369 0.014694631307311828" type="sphere" size="0.08" class="collision" />
            <geom name="wheel_3_collision_2" pos="0 0.007725424859373687 0.02377641290737884" type="sphere" size="0.08" class="collision" />
            <geom name="wheel_3_collision_3" pos="0 -0.007725424859373684 0.023776412907378842" type="sphere" size="0.08" class="collision" />
            <geom name="wheel_3_collision_4" pos="0 -0.020225424859373686 0.014694631307311832" type="sphere" size="0.08" class="collision" />
            <geom name="wheel_3_collision_5" pos="0 -0.025 3.061616997868383e-18" type="sphere" size="0.08" class="collision" />
            <geom name="wheel_3_collision_6" pos="0 -0.02022542485937369 -0.014694631307311827" type="sphere" size="0.08" class="collision" />
            <geom name="wheel_3_collision_7" pos="0 -0.007725424859373689 -0.02377641290737884" type="sphere" size="0.08" class="collision" />
            <geom name="wheel_3_collision_8" pos="0 0.007725424859373681 -0.023776412907378842" type="sphere" size="0.08" class="collision" />
            <geom name="wheel_3_collision_9" pos="0 0.020225424859373686 -0.014694631307311835" type="sphere" size="0.08" class="collision" />
            <geom type="mesh" class="visual" name="wheel_3_visual_0" mesh="wheel_1_omniwheel_10_0" material="d405_black" />
            <geom type="mesh" class="visual" name="wheel_3_visual_1" mesh="wheel_1_omniwheel_10_1" material="leg2_logo_white" />
            <geom type="mesh" class="visual" name="wheel_3_visual_2" mesh="wheel_3_merged_wheel" material="omniwheel_10_wheel" pos="0 0 0" />
          </body>
          <body name="wheel_4" pos="0.176493 -0.176493 0.071834" quat="0.3827 0 0 0.9239">
            <inertial pos="0.0026089441594678298 -1.3189703553351252e-07 2.8695680726054107e-07" mass="4.24803000494366" diaginertia="0.012235 0.006629 0.006629" />
            <geom name="wheel_4_collision_0" pos="0 0.025 0.0" type="sphere" size="0.08" class="collision" />
            <geom name="wheel_4_collision_1" pos="0 0.02022542485937369 0.014694631307311828" type="sphere" size="0.08" class="collision" />
            <geom name="wheel_4_collision_2" pos="0 0.007725424859373687 0.02377641290737884" type="sphere" size="0.08" class="collision" />
            <geom name="wheel_4_collision_3" pos="0 -0.007725424859373684 0.023776412907378842" type="sphere" size="0.08" class="collision" />
            <geom name="wheel_4_collision_4" pos="0 -0.020225424859373686 0.014694631307311832" type="sphere" size="0.08" class="collision" />
            <geom name="wheel_4_collision_5" pos="0 -0.025 3.061616997868383e-18" type="sphere" size="0.08" class="collision" />
            <geom name="wheel_4_collision_6" pos="0 -0.02022542485937369 -0.014694631307311827" type="sphere" size="0.08" class="collision" />
            <geom name="wheel_4_collision_7" pos="0 -0.007725424859373689 -0.02377641290737884" type="sphere" size="0.08" class="collision" />
            <geom name="wheel_4_collision_8" pos="0 0.007725424859373681 -0.023776412907378842" type="sphere" size="0.08" class="collision" />
            <geom name="wheel_4_collision_9" pos="0 0.020225424859373686 -0.014694631307311835" type="sphere" size="0.08" class="collision" />
            <geom type="mesh" class="visual" name="wheel_4_visual_0" mesh="wheel_1_omniwheel_10_0" material="d405_black" />
            <geom type="mesh" class="visual" name="wheel_4_visual_1" mesh="wheel_1_omniwheel_10_1" material="leg2_logo_white" />
            <geom type="mesh" class="visual" name="wheel_4_visual_2" mesh="wheel_4_merged_wheel" material="omniwheel_10_wheel" pos="0 0 0" />
          </body>
          <body name="chassis_lidar" pos="0.235 0 0.2144">
            <geom type="mesh" class="visual" name="chassis_lidar_visual_0" mesh="chassis_lidar_mid360_0" material="mid360_blue" />
            <geom type="mesh" class="visual" name="chassis_lidar_visual_1" mesh="chassis_lidar_mid360_1" material="mid360_silver" />
            <geom type="mesh" class="visual" name="chassis_lidar_visual_2" mesh="chassis_lidar_mid360_2" material="mid360_white" />
          </body>
        </body>
      </body>
      <freejoint name="floating_base" />
    </body>
    <light pos="0 0 2." dir="0 0 -1" directional="true" />
    <geom name="floor" class="floor" size="0 0 0.05" />
  </worldbody>

  <asset>
    <material name="chassis_green_light" rgba="0.14117647 0.80000000 0.00000000 1.0" />
    <material name="chassis_metal_aluminum" rgba="0.81960784 0.81960784 0.81960784 1.0" />
    <material name="chassis_light_silver" rgba="0.73725490 0.73725490 0.73725490 1.0" />
    <material name="chassis_medium_yellow" rgba="0.90196078 0.36078431 0.00000000 1.0" />
    <material name="chassis_plastic_gary" rgba="0.43529412 0.43529412 0.43529412 1.0" />
    <material name="chassis_plastic_black" rgba="0.02352941 0.02352941 0.02352941 1.0" />
    <material name="chassis_glacier_white" rgba="0.89803922 0.89803922 0.89803922 1.0" />
    <material name="leg1_metal_black" rgba="0.04313725 0.04313725 0.04313725 1.0" />
    <material name="leg2_screw_white" rgba="0.63137255 0.63137255 0.63137255 1.0" />
    <material name="leg2_plastic_white" rgba="0.85098039 0.85098039 0.85098039 1.0" />
    <material name="leg2_logo_white" rgba="0.40000000 0.40000000 0.40000000 1.0" />
    <material name="torso_emergency_stop_switch" rgba="0.80000000 0.00000000 0.00000000 1.0" />
    <material name="torso_camera" rgba="0.00000000 0.00000000 0.00000000 1.0" />
    <material name="torso_white_light" rgba="0.80000000 0.80000000 0.80000000 1.0" />
    <material name="torso_Emergency_stop_tail" rgba="0.98431373 0.49019608 0.01568627 1.0" />
    <material name="head_link2_glacier_428c" rgba="0.22745098 0.25098039 0.25098039 1.0" />
    <material name="link3_metal_aluminum" rgba="0.69803922 0.69803922 0.69803922 1.0" />
    <material name="d405_black" rgba="0.01176471 0.01176471 0.01176471 1.0" />
    <material name="d405_silver" rgba="0.64705882 0.64705882 0.64705882 1.0" />
    <material name="omniwheel_10_wheel" rgba="0.05098039 0.05098039 0.05098039 1.0" />
    <material name="mid360_white" rgba="0.70196078 0.75686275 0.80000000 1.0" />
    <material name="mid360_silver" rgba="0.50196078 0.50196078 0.50196078 1.0" />
    <material name="mid360_blue" rgba="0.01176471 0.03529412 0.14509804 1.0" />
    <mesh name="leg_link1_collision_link1" file="meshes/galbot_one_golf_description/meshes/collision/leg/link1.stl" />
    <mesh name="leg_link1_leg1" file="meshes/galbot_one_golf_description/meshes/visual/leg/leg1.obj" />
    <mesh name="leg_link2_collision_link2" file="meshes/galbot_one_golf_description/meshes/collision/leg/link2.stl" />
    <mesh name="leg_link3_collision_link3" file="meshes/galbot_one_golf_description/meshes/collision/leg/link3.stl" />
    <mesh name="leg_link3_leg3" file="meshes/galbot_one_golf_description/meshes/visual/leg/leg3.obj" />
    <mesh name="leg_link4_leg4" file="meshes/galbot_one_golf_description/meshes/visual/leg/leg4.obj" />
    <mesh name="torso_base_link_collision_torso" file="meshes/galbot_one_golf_description/meshes/collision/torso.stl" />
    <mesh name="head_link1_collision_head_link1" file="meshes/galbot_one_golf_description/meshes/collision/head/head_link1.stl" />
    <mesh name="head_link1_head_link1" file="meshes/galbot_one_golf_description/meshes/visual/head/head_link1.obj" />
    <mesh name="head_link2_collision_head_link2" file="meshes/galbot_one_golf_description/meshes/collision/head/head_link2.stl" />
    <mesh name="left_arm_link1_collision_link1" file="meshes/galbot_one_golf_description/meshes/collision/arm/link1.stl" />
    <mesh name="left_arm_link1_link1" file="meshes/galbot_one_golf_description/meshes/visual/arm/link1.obj" />
    <mesh name="left_arm_link2_collision_link2" file="meshes/galbot_one_golf_description/meshes/collision/arm/link2.stl" />
    <mesh name="left_arm_link3_collision_link3" file="meshes/galbot_one_golf_description/meshes/collision/arm/link3.stl" />
    <mesh name="left_arm_link4_collision_link4" file="meshes/galbot_one_golf_description/meshes/collision/arm/link4.stl" />
    <mesh name="left_arm_link5_collision_link5" file="meshes/galbot_one_golf_description/meshes/collision/arm/link5.stl" />
    <mesh name="left_arm_link6_collision_link6" file="meshes/galbot_one_golf_description/meshes/collision/arm/link6.stl" />
    <mesh name="left_arm_link7_collision_link7" file="meshes/galbot_one_golf_description/meshes/collision/arm/link7.stl" />
    <mesh name="left_gripper_flange_link_flange" file="meshes/galbot_one_golf_description/meshes/visual/end_effectors/galbot_gripper/flange.obj" />
    <mesh name="left_gripper_base_link_collision_base_link" file="meshes/galbot_one_golf_description/meshes/collision/end_effectors/galbot_gripper/base_link.stl" />
    <mesh name="left_gripper_r_knuckle_link_collision_link_1" file="meshes/galbot_one_golf_description/meshes/collision/end_effectors/galbot_gripper/link_1.stl" />
    <mesh name="left_gripper_r_inner_knuckle_link_collision_link_2" file="meshes/galbot_one_golf_description/meshes/collision/end_effectors/galbot_gripper/link_2.stl" />
    <mesh name="left_gripper_r_finger_link_collision_link_3" file="meshes/galbot_one_golf_description/meshes/collision/end_effectors/galbot_gripper/link_3.stl" />
    <mesh name="left_gripper_r_finger_link_collision_link_3_1" file="meshes/galbot_one_golf_description/meshes/collision/end_effectors/galbot_gripper/link_3_scaled_1_m1_1.stl" />
    <mesh name="left_gripper_l_finger_link_collision_link_3" file="meshes/galbot_one_golf_description/meshes/collision/end_effectors/galbot_gripper/link_3.stl" />
    <mesh name="left_arm_wrist_camera_stand_collision_d405" file="meshes/galbot_one_golf_description/meshes/collision/d405.stl" />
    <mesh name="left_arm_wrist_camera_stand_d405_stand" file="meshes/galbot_one_golf_description/meshes/visual/arm/d405_stand.obj" />
    <mesh name="right_arm_link1_collision_link1" file="meshes/galbot_one_golf_description/meshes/collision/arm/link1.stl" />
    <mesh name="right_arm_link1_collision_link1_1" file="meshes/galbot_one_golf_description/meshes/collision/arm/link1_scaled_1_m1_1.stl" />
    <mesh name="right_arm_link1_link1" file="meshes/galbot_one_golf_description/meshes/visual/arm/link1.obj" />
    <mesh name="right_arm_link1_link1_1" file="meshes/galbot_one_golf_description/meshes/visual/arm/link1_scaled_1_m1_1.obj" />
    <mesh name="right_arm_link2_collision_link2" file="meshes/galbot_one_golf_description/meshes/collision/arm/link2.stl" />
    <mesh name="right_arm_link2_collision_link2_1" file="meshes/galbot_one_golf_description/meshes/collision/arm/link2_scaled_1_m1_1.stl" />
    <mesh name="right_arm_link2_link2_right" file="meshes/galbot_one_golf_description/meshes/visual/arm/link2_right.obj" />
    <mesh name="right_arm_link3_collision_link3" file="meshes/galbot_one_golf_description/meshes/collision/arm/link3.stl" />
    <mesh name="right_arm_link3_collision_link3_1" file="meshes/galbot_one_golf_description/meshes/collision/arm/link3_scaled_1_m1_1.stl" />
    <mesh name="right_arm_link4_collision_link4" file="meshes/galbot_one_golf_description/meshes/collision/arm/link4.stl" />
    <mesh name="right_arm_link4_collision_link4_1" file="meshes/galbot_one_golf_description/meshes/collision/arm/link4_scaled_1_m1_1.stl" />
    <mesh name="right_arm_link6_collision_link6" file="meshes/galbot_one_golf_description/meshes/collision/arm/link6.stl" />
    <mesh name="right_arm_link6_collision_link6_1" file="meshes/galbot_one_golf_description/meshes/collision/arm/link6_scaled_1_m1_1.stl" />
    <mesh name="right_arm_link7_collision_link7" file="meshes/galbot_one_golf_description/meshes/collision/arm/link7.stl" />
    <mesh name="right_arm_link7_collision_link7_1" file="meshes/galbot_one_golf_description/meshes/collision/arm/link7_scaled_1_m1_1.stl" />
    <mesh name="omni_chassis_base_link_chassis_0" file="meshes/galbot_one_golf_description/meshes/visual/chassis/chassis/chassis_0.obj" />
    <mesh name="omni_chassis_base_link_chassis_1" file="meshes/galbot_one_golf_description/meshes/visual/chassis/chassis/chassis_1.obj" />
    <mesh name="omni_chassis_base_link_chassis_2" file="meshes/galbot_one_golf_description/meshes/visual/chassis/chassis/chassis_2.obj" />
    <mesh name="omni_chassis_base_link_chassis_3" file="meshes/galbot_one_golf_description/meshes/visual/chassis/chassis/chassis_3.obj" />
    <mesh name="omni_chassis_base_link_chassis_4" file="meshes/galbot_one_golf_description/meshes/visual/chassis/chassis/chassis_4.obj" />
    <mesh name="omni_chassis_base_link_chassis_5" file="meshes/galbot_one_golf_description/meshes/visual/chassis/chassis/chassis_5.obj" />
    <mesh name="omni_chassis_base_link_chassis_6" file="meshes/galbot_one_golf_description/meshes/visual/chassis/chassis/chassis_6.obj" />
    <mesh name="leg_link2_leg2_0" file="meshes/galbot_one_golf_description/meshes/visual/leg/leg2/leg2_0.obj" />
    <mesh name="leg_link2_leg2_1" file="meshes/galbot_one_golf_description/meshes/visual/leg/leg2/leg2_1.obj" />
    <mesh name="leg_link2_leg2_2" file="meshes/galbot_one_golf_description/meshes/visual/leg/leg2/leg2_2.obj" />
    <mesh name="leg_link2_leg2_3" file="meshes/galbot_one_golf_description/meshes/visual/leg/leg2/leg2_3.obj" />
    <mesh name="torso_base_link_torso_0" file="meshes/galbot_one_golf_description/meshes/visual/torso/torso/torso_0.obj" />
    <mesh name="torso_base_link_torso_1" file="meshes/galbot_one_golf_description/meshes/visual/torso/torso/torso_1.obj" />
    <mesh name="torso_base_link_torso_2" file="meshes/galbot_one_golf_description/meshes/visual/torso/torso/torso_2.obj" />
    <mesh name="torso_base_link_torso_3" file="meshes/galbot_one_golf_description/meshes/visual/torso/torso/torso_3.obj" />
    <mesh name="torso_base_link_torso_4" file="meshes/galbot_one_golf_description/meshes/visual/torso/torso/torso_4.obj" />
    <mesh name="torso_base_link_torso_5" file="meshes/galbot_one_golf_description/meshes/visual/torso/torso/torso_5.obj" />
    <mesh name="torso_base_link_torso_6" file="meshes/galbot_one_golf_description/meshes/visual/torso/torso/torso_6.obj" />
    <mesh name="torso_base_link_torso_7" file="meshes/galbot_one_golf_description/meshes/visual/torso/torso/torso_7.obj" />
    <mesh name="torso_base_link_torso_8" file="meshes/galbot_one_golf_description/meshes/visual/torso/torso/torso_8.obj" />
    <mesh name="torso_base_link_torso_9" file="meshes/galbot_one_golf_description/meshes/visual/torso/torso/torso_9.obj" />
    <mesh name="head_link2_head_link2_0" file="meshes/galbot_one_golf_description/meshes/visual/head/head_link2/head_link2_0.obj" />
    <mesh name="head_link2_head_link2_1" file="meshes/galbot_one_golf_description/meshes/visual/head/head_link2/head_link2_1.obj" />
    <mesh name="head_link2_head_link2_2" file="meshes/galbot_one_golf_description/meshes/visual/head/head_link2/head_link2_2.obj" />
    <mesh name="head_link2_head_link2_3" file="meshes/galbot_one_golf_description/meshes/visual/head/head_link2/head_link2_3.obj" />
    <mesh name="head_link2_head_link2_4" file="meshes/galbot_one_golf_description/meshes/visual/head/head_link2/head_link2_4.obj" />
    <mesh name="left_arm_link2_link2_0" file="meshes/galbot_one_golf_description/meshes/visual/arm/link2/link2_0.obj" />
    <mesh name="left_arm_link2_link2_1" file="meshes/galbot_one_golf_description/meshes/visual/arm/link2/link2_1.obj" />
    <mesh name="left_arm_link3_link3_0" file="meshes/galbot_one_golf_description/meshes/visual/arm/link3/link3_0.obj" />
    <mesh name="left_arm_link3_link3_1" file="meshes/galbot_one_golf_description/meshes/visual/arm/link3/link3_1.obj" />
    <mesh name="left_arm_link4_link4_0" file="meshes/galbot_one_golf_description/meshes/visual/arm/link4/link4_0.obj" />
    <mesh name="left_arm_link4_link4_1" file="meshes/galbot_one_golf_description/meshes/visual/arm/link4/link4_1.obj" />
    <mesh name="left_arm_link5_link5_0" file="meshes/galbot_one_golf_description/meshes/visual/arm/link5/link5_0.obj" />
    <mesh name="left_arm_link5_link5_1" file="meshes/galbot_one_golf_description/meshes/visual/arm/link5/link5_1.obj" />
    <mesh name="left_arm_link6_link6_0" file="meshes/galbot_one_golf_description/meshes/visual/arm/link6/link6_0.obj" />
    <mesh name="left_arm_link6_link6_1" file="meshes/galbot_one_golf_description/meshes/visual/arm/link6/link6_1.obj" />
    <mesh name="left_arm_link7_link7_0" file="meshes/galbot_one_golf_description/meshes/visual/arm/link7/link7_0.obj" />
    <mesh name="left_arm_link7_link7_1" file="meshes/galbot_one_golf_description/meshes/visual/arm/link7/link7_1.obj" />
    <mesh name="left_arm_link7_link7_2" file="meshes/galbot_one_golf_description/meshes/visual/arm/link7/link7_2.obj" />
    <mesh name="left_gripper_base_link_base_link_0" file="meshes/galbot_one_golf_description/meshes/visual/end_effectors/galbot_gripper/base_link/base_link_0.obj" />
    <mesh name="left_gripper_base_link_base_link_1" file="meshes/galbot_one_golf_description/meshes/visual/end_effectors/galbot_gripper/base_link/base_link_1.obj" />
    <mesh name="left_gripper_r_knuckle_link_link1_0" file="meshes/galbot_one_golf_description/meshes/visual/end_effectors/galbot_gripper/link1/link1_0.obj" />
    <mesh name="left_gripper_r_knuckle_link_link1_1" file="meshes/galbot_one_golf_description/meshes/visual/end_effectors/galbot_gripper/link1/link1_1.obj" />
    <mesh name="left_gripper_r_inner_knuckle_link_link2_0" file="meshes/galbot_one_golf_description/meshes/visual/end_effectors/galbot_gripper/link2/link2_0.obj" />
    <mesh name="left_gripper_r_inner_knuckle_link_link2_1" file="meshes/galbot_one_golf_description/meshes/visual/end_effectors/galbot_gripper/link2/link2_1.obj" />
    <mesh name="left_gripper_r_finger_link_link3_0" file="meshes/galbot_one_golf_description/meshes/visual/end_effectors/galbot_gripper/link3/link3_0.obj" />
    <mesh name="left_gripper_r_finger_link_link3_0_1" file="meshes/galbot_one_golf_description/meshes/visual/end_effectors/galbot_gripper/link3/link3_0_scaled_1_m1_1.obj" />
    <mesh name="left_gripper_r_finger_link_link3_1" file="meshes/galbot_one_golf_description/meshes/visual/end_effectors/galbot_gripper/link3/link3_1.obj" />
    <mesh name="left_gripper_r_finger_link_link3_1_1" file="meshes/galbot_one_golf_description/meshes/visual/end_effectors/galbot_gripper/link3/link3_1_scaled_1_m1_1.obj" />
    <mesh name="left_gripper_r_finger_link_link3_2" file="meshes/galbot_one_golf_description/meshes/visual/end_effectors/galbot_gripper/link3/link3_2.obj" />
    <mesh name="left_gripper_r_finger_link_link3_2_1" file="meshes/galbot_one_golf_description/meshes/visual/end_effectors/galbot_gripper/link3/link3_2_scaled_1_m1_1.obj" />
    <mesh name="left_gripper_l_finger_link_link3_0" file="meshes/galbot_one_golf_description/meshes/visual/end_effectors/galbot_gripper/link3/link3_0.obj" />
    <mesh name="left_gripper_l_finger_link_link3_1" file="meshes/galbot_one_golf_description/meshes/visual/end_effectors/galbot_gripper/link3/link3_1.obj" />
    <mesh name="left_gripper_l_finger_link_link3_2" file="meshes/galbot_one_golf_description/meshes/visual/end_effectors/galbot_gripper/link3/link3_2.obj" />
    <mesh name="left_wrist_camera_link_d405_0" file="meshes/galbot_one_golf_description/meshes/visual/sensors/realsense/d405/d405_0.obj" inertia="shell" />
    <mesh name="left_wrist_camera_link_d405_1" file="meshes/galbot_one_golf_description/meshes/visual/sensors/realsense/d405/d405_1.obj" />
    <mesh name="left_wrist_camera_link_d405_2" file="meshes/galbot_one_golf_description/meshes/visual/sensors/realsense/d405/d405_2.obj" />
    <mesh name="right_arm_link3_link3_0" file="meshes/galbot_one_golf_description/meshes/visual/arm/link3/link3_0.obj" />
    <mesh name="right_arm_link3_link3_0_1" file="meshes/galbot_one_golf_description/meshes/visual/arm/link3/link3_0_scaled_1_m1_1.obj" />
    <mesh name="right_arm_link3_link3_1" file="meshes/galbot_one_golf_description/meshes/visual/arm/link3/link3_1.obj" />
    <mesh name="right_arm_link3_link3_1_1" file="meshes/galbot_one_golf_description/meshes/visual/arm/link3/link3_1_scaled_1_m1_1.obj" />
    <mesh name="right_arm_link4_link4_0" file="meshes/galbot_one_golf_description/meshes/visual/arm/link4/link4_0.obj" />
    <mesh name="right_arm_link4_link4_0_1" file="meshes/galbot_one_golf_description/meshes/visual/arm/link4/link4_0_scaled_1_m1_1.obj" />
    <mesh name="right_arm_link4_link4_1" file="meshes/galbot_one_golf_description/meshes/visual/arm/link4/link4_1.obj" />
    <mesh name="right_arm_link4_link4_1_1" file="meshes/galbot_one_golf_description/meshes/visual/arm/link4/link4_1_scaled_1_m1_1.obj" />
    <mesh name="right_arm_link6_link6_0" file="meshes/galbot_one_golf_description/meshes/visual/arm/link6/link6_0.obj" />
    <mesh name="right_arm_link6_link6_0_1" file="meshes/galbot_one_golf_description/meshes/visual/arm/link6/link6_0_scaled_1_m1_1.obj" />
    <mesh name="right_arm_link6_link6_1" file="meshes/galbot_one_golf_description/meshes/visual/arm/link6/link6_1.obj" />
    <mesh name="right_arm_link6_link6_1_1" file="meshes/galbot_one_golf_description/meshes/visual/arm/link6/link6_1_scaled_1_m1_1.obj" />
    <mesh name="right_arm_link7_link7_0" file="meshes/galbot_one_golf_description/meshes/visual/arm/link7/link7_0.obj" />
    <mesh name="right_arm_link7_link7_0_1" file="meshes/galbot_one_golf_description/meshes/visual/arm/link7/link7_0_scaled_1_m1_1.obj" />
    <mesh name="right_arm_link7_link7_1" file="meshes/galbot_one_golf_description/meshes/visual/arm/link7/link7_1.obj" />
    <mesh name="right_arm_link7_link7_1_1" file="meshes/galbot_one_golf_description/meshes/visual/arm/link7/link7_1_scaled_1_m1_1.obj" />
    <mesh name="right_arm_link7_link7_2" file="meshes/galbot_one_golf_description/meshes/visual/arm/link7/link7_2.obj" />
    <mesh name="right_arm_link7_link7_2_1" file="meshes/galbot_one_golf_description/meshes/visual/arm/link7/link7_2_scaled_1_m1_1.obj" />
    <mesh name="wheel_1_omniwheel_10_0" file="meshes/galbot_one_golf_description/meshes/visual/components/omniwheel_10/omniwheel_10_0.obj" />
    <mesh name="wheel_1_omniwheel_10_1" file="meshes/galbot_one_golf_description/meshes/visual/components/omniwheel_10/omniwheel_10_1.obj" />
    <mesh name="chassis_lidar_mid360_0" file="meshes/galbot_one_golf_description/meshes/visual/sensors/mid360/mid360/mid360_0.obj" />
    <mesh name="chassis_lidar_mid360_1" file="meshes/galbot_one_golf_description/meshes/visual/sensors/mid360/mid360/mid360_1.obj" />
    <mesh name="chassis_lidar_mid360_2" file="meshes/galbot_one_golf_description/meshes/visual/sensors/mid360/mid360/mid360_2.obj" />
    <mesh name="wheel_1_merged_wheel" file="meshes/galbot_one_golf_description/meshes/visual/components/omniwheel_10/wheel_1_merged_wheel.obj" />
    <mesh name="wheel_2_merged_wheel" file="meshes/galbot_one_golf_description/meshes/visual/components/omniwheel_10/wheel_2_merged_wheel.obj" />
    <mesh name="wheel_3_merged_wheel" file="meshes/galbot_one_golf_description/meshes/visual/components/omniwheel_10/wheel_3_merged_wheel.obj" />
    <mesh name="wheel_4_merged_wheel" file="meshes/galbot_one_golf_description/meshes/visual/components/omniwheel_10/wheel_4_merged_wheel.obj" />
    <texture type="2d" name="groundplane" builtin="checker" mark="edge" rgb1="0.2 0.3 0.4" rgb2="0.1 0.2 0.3" markrgb="0.8 0.8 0.8" width="300" height="300" />
    <material name="groundplane" texture="groundplane" texuniform="true" texrepeat="5 5" reflectance="0.2" />
    <texture type="skybox" builtin="gradient" rgb1="0.3 0.5 0.7" rgb2="0 0 0" width="512" height="3072" />
  </asset>

  <actuator>
    <position name="leg_joint1" joint="leg_joint1" class="leg_joint" kp="120000.0" kv="12000.0" ctrlrange="0.0 0.9374" />
    <position name="leg_joint2" joint="leg_joint2" class="leg_joint" kp="120000.0" kv="12000.0" ctrlrange="0.0 2.5847" />
    <position name="leg_joint3" joint="leg_joint3" class="leg_joint" kp="57000.0" kv="5700.0" ctrlrange="0.0 2.3262" forcerange="-420.0 420.0" />
    <position name="leg_joint4" joint="leg_joint4" class="leg_joint" kp="16000.0" kv="1600.0" ctrlrange="-1.5906 1.5906" forcerange="-150.0 150.0" />
    <position name="leg_joint5" joint="leg_joint5" class="leg_joint" kp="16000.0" kv="1600.0" ctrlrange="-0.1645 0.1645" forcerange="-150.0 150.0" />
    <position name="head_joint1" joint="head_joint1" class="head_joint" kp="3400.0" kv="340.0" ctrlrange="-1.5208 1.5208" />
    <position name="head_joint2" joint="head_joint2" class="head_joint" kp="3400.0" kv="340.0" ctrlrange="-0.2143461 0.4935988" />
    <position name="right_arm_joint1" joint="right_arm_joint1" class="arm_joint_upper" kp="15000.0" kv="1500.0" ctrlrange="-3.00432619 3.00432619" forcerange="-60.0 60.0" />
    <position name="right_arm_joint2" joint="right_arm_joint2" class="arm_joint_upper" kp="15000.0" kv="1500.0" ctrlrange="-1.608062789 1.608062789" forcerange="-60.0 60.0" />
    <position name="right_arm_joint3" joint="right_arm_joint3" class="arm_joint_lower" kp="7000.0" kv="700.0" ctrlrange="-2.916972222 2.916972222" forcerange="-30.0 30.0" />
    <position name="right_arm_joint4" joint="right_arm_joint4" class="arm_joint_lower" kp="7000.0" kv="700.0" ctrlrange="-1.869862177 2.5679938779914946" forcerange="-30.0 30.0" />
    <position name="right_arm_joint5" joint="right_arm_joint5" class="arm_joint_lower" kp="3500.0" kv="350.0" ctrlrange="-2.916972222 2.916972222" forcerange="-10.0 10.0" />
    <position name="right_arm_joint6" joint="right_arm_joint6" class="arm_joint_lower" kp="3500.0" kv="350.0" ctrlrange="-0.7353981633974483 0.8226646259971648" forcerange="-10.0 10.0" />
    <position name="right_arm_joint7" joint="right_arm_joint7" class="arm_joint_lower" kp="3500.0" kv="350.0" ctrlrange="-1.538202778 1.538202778" forcerange="-10.0 10.0" />
    <position name="left_arm_joint1" joint="left_arm_joint1" class="arm_joint_upper" kp="15000.0" kv="1500.0" ctrlrange="-3.00432619 3.00432619" />
    <position name="left_arm_joint2" joint="left_arm_joint2" class="arm_joint_upper" kp="15000.0" kv="1500.0" ctrlrange="-1.608062789 1.608062789" />
    <position name="left_arm_joint3" joint="left_arm_joint3" class="arm_joint_lower" kp="7000.0" kv="700.0" ctrlrange="-2.916972222 2.916972222" />
    <position name="left_arm_joint4" joint="left_arm_joint4" class="arm_joint_lower" kp="7000.0" kv="700.0" ctrlrange="-2.5679938779914946 1.869862177" />
    <position name="left_arm_joint5" joint="left_arm_joint5" class="arm_joint_lower" kp="3500.0" kv="350.0" ctrlrange="-2.916972222 2.916972222" forcerange="-10.0 10.0" />
    <position name="left_arm_joint6" joint="left_arm_joint6" class="arm_joint_lower" kp="3500.0" kv="350.0" ctrlrange="-0.8226646259971648 0.7353981633974483" forcerange="-10.0 10.0" />
    <position name="left_arm_joint7" joint="left_arm_joint7" class="arm_joint_lower" kp="3500.0" kv="350.0" ctrlrange="-1.538202778 1.538202778" forcerange="-10.0 10.0" />
    <position name="right_gripper_joint" joint="right_gripper_joint" class="gripper_joint" ctrlrange="0.0 1.703" />
    <position name="left_gripper_joint" joint="left_gripper_joint" class="gripper_joint" ctrlrange="0.0 1.703" />
  </actuator>

  <equality>
    <joint joint1="right_gripper_joint" joint2="right_gripper_r_inner_knuckle_joint" polycoef="0.0 -1.0 0 0 0" solimp="0.95 0.99 0.001" solref="0.005 1" />
    <joint joint1="right_gripper_joint" joint2="right_gripper_r_finger_joint" polycoef="0.0 1.0 0 0 0" solimp="0.95 0.99 0.001" solref="0.005 1" />
    <joint joint1="right_gripper_joint" joint2="right_gripper_l_knuckle_joint" polycoef="0.0 1.0 0 0 0" solimp="0.95 0.99 0.001" solref="0.005 1" />
    <joint joint1="right_gripper_joint" joint2="right_gripper_l_inner_knuckle_joint" polycoef="0.0 1.0 0 0 0" solimp="0.95 0.99 0.001" solref="0.005 1" />
    <joint joint1="right_gripper_joint" joint2="right_gripper_l_finger_joint" polycoef="0.0 -1.0 0 0 0" solimp="0.95 0.99 0.001" solref="0.005 1" />
    <joint joint1="left_gripper_joint" joint2="left_gripper_r_inner_knuckle_joint" polycoef="0.0 -1.0 0 0 0" solimp="0.95 0.99 0.001" solref="0.005 1" />
    <joint joint1="left_gripper_joint" joint2="left_gripper_r_finger_joint" polycoef="0.0 1.0 0 0 0" solimp="0.95 0.99 0.001" solref="0.005 1" />
    <joint joint1="left_gripper_joint" joint2="left_gripper_l_knuckle_joint" polycoef="0.0 1.0 0 0 0" solimp="0.95 0.99 0.001" solref="0.005 1" />
    <joint joint1="left_gripper_joint" joint2="left_gripper_l_inner_knuckle_joint" polycoef="0.0 1.0 0 0 0" solimp="0.95 0.99 0.001" solref="0.005 1" />
    <joint joint1="left_gripper_joint" joint2="left_gripper_l_finger_joint" polycoef="0.0 -1.0 0 0 0" solimp="0.95 0.99 0.001" solref="0.005 1" />
  </equality>

  <visual>
    <rgba haze="0.15 0.25 0.35 1" />
  </visual>

  <option integrator="implicitfast" />

  <sensor>
    <jointvel name="vel_leg_joint1" joint="leg_joint1" />
    <jointvel name="vel_leg_joint2" joint="leg_joint2" />
    <jointvel name="vel_leg_joint3" joint="leg_joint3" />
    <jointvel name="vel_leg_joint4" joint="leg_joint4" />
    <jointvel name="vel_leg_joint5" joint="leg_joint5" />
    <jointvel name="vel_head_joint1" joint="head_joint1" />
    <jointvel name="vel_head_joint2" joint="head_joint2" />
    <jointvel name="vel_right_arm_joint1" joint="right_arm_joint1" />
    <jointvel name="vel_right_arm_joint2" joint="right_arm_joint2" />
    <jointvel name="vel_right_arm_joint3" joint="right_arm_joint3" />
    <jointvel name="vel_right_arm_joint4" joint="right_arm_joint4" />
    <jointvel name="vel_right_arm_joint5" joint="right_arm_joint5" />
    <jointvel name="vel_right_arm_joint6" joint="right_arm_joint6" />
    <jointvel name="vel_right_arm_joint7" joint="right_arm_joint7" />
    <jointvel name="vel_left_arm_joint1" joint="left_arm_joint1" />
    <jointvel name="vel_left_arm_joint2" joint="left_arm_joint2" />
    <jointvel name="vel_left_arm_joint3" joint="left_arm_joint3" />
    <jointvel name="vel_left_arm_joint4" joint="left_arm_joint4" />
    <jointvel name="vel_left_arm_joint5" joint="left_arm_joint5" />
    <jointvel name="vel_left_arm_joint6" joint="left_arm_joint6" />
    <jointvel name="vel_left_arm_joint7" joint="left_arm_joint7" />
  </sensor>
</mujoco>